Workbook
Name Slicer_ACTUAL_OD: #N/A
Name Slicer_Bucket: #N/A
Name Slicer_CUSTOMER_NAME1: #N/A
Name Slicer_GRADE: #N/A
Name Slicer_Grade1: #N/A
Name Slicer_ID: #N/A
Name Slicer_ID1: #N/A
Name Slicer_Length: #N/A
Name Slicer_LENGTH1: #N/A
Name Slicer_Material_Type: #N/A
Name Slicer_OD: #N/A
Name Slicer_OD2: #N/A
Name Slicer_Plant: #N/A
Name Slicer_SCHEDULE: #N/A
Name Slicer_TDC: #N/A
Name Slicer_Thickness: #N/A
Name Slicer_THIK: #N/A
Name Slicer_THK: #N/A
Name Slicer_TICKNESS: #N/A

Sheet Sheet2
A1: Last refreshed: 9/28/2025, 5:30:27 AM

Sheet OEM_key_1_rev codes
A1: Customer | B1: OEM | C1: CAM
A2: A.R.Automotive And Engg Industries | B2: RE | C2: Abhishek
A3: BALAJI INDUSTRIES | B3: HMSIL | C3: Abhishek
A4: BALAJI PRESS PRODUCTS INDIA | B4: TVS | C4: Apoorv
A5: BCC PIPES & TUBES PRIVATE LIMITED | B5: GE | C5: Jitendra
A6: BHARAT TUBES CORPORATION | B6: Boiler | C6: Jitendra
A7: ELKAYEM AUTO ANCILLARIES (PVT) LTD. | B7: TVS | C7: Apoorv
A8: ELKAYEM AUTO ANCILLARIES PRIVATE LI | B8: TVS | C8: Apoorv
A9: ELKAYEM AUTO ANCILLARIES PVT LTD -U | B9: TVS | C9: Apoorv
A10: GANESH INDUSTRAIL SUPPLIES | B10: Boiler | C10: Jitendra
A11: Indo Autotech Limited (Unit V) | B11: HMSIL | C11: Abhishek
A12: JBM AUTO LIMITED | B12: RE | C12: Abhishek
... A175: A R AUTOMOTIVE INDUSTRIES PRIVATE L | B175: RE | C175: Abhishek

Sheet RM Coil
A1: Grade | B1: TDC | C1: THIK | D1: Key | E1: MATERIAL | F1: Material Description
A2: Micro alloy | B2: BR45 | C2: 1.6 | D2: =_xlfn.CONCAT(Table32[[#This Row],[TDC]],"-",Table32[[#This Row],[THIK]]) | E2: 3820031 | F2: CR COIL TATXHS BR45 1.600X1300
A3: Micro alloy | B3: BR03 | C3: 1.6 | D3: =_xlfn.CONCAT(Table32[[#This Row],[TDC]],"-",Table32[[#This Row],[THIK]]) | E3: 3717652 | F3: CR COIL TATXHS BR03 1.600X1300
A4: Micro alloy | B4: BR03 | C4: 1.6 | D4: =_xlfn.CONCAT(Table32[[#This Row],[TDC]],"-",Table32[[#This Row],[THIK]]) | E4: 3959449 | F4: CR COIL TATXHS BR03 1.600X1250
A5: Micro alloy | B5: BR45 | C5: 2 | D5: =_xlfn.CONCAT(Table32[[#This Row],[TDC]],"-",Table32[[#This Row],[THIK]]) | E5: 3820032 | F5: CR COIL TATXHS BR45 2X1300
A6: Micro alloy | B6: BR03 | C6: 2 | D6: =_xlfn.CONCAT(Table32[[#This Row],[TDC]],"-",Table32[[#This Row],[THIK]]) | E6: 3717653 | F6: CR COIL TATXHS BR03 2X1300
A7: Micro alloy | B7: BR03 | C7: 2 | D7: =_xlfn.CONCAT(Table32[[#This Row],[TDC]],"-",Table32[[#This Row],[THIK]]) | E7: 3959450 | F7: CR COIL TATXHS BR03 2X1250
A8: Micro alloy | B8: BR45 | C8: 2.3 | D8: =_xlfn.CONCAT(Table32[[#This Row],[TDC]],"-",Table32[[#This Row],[THIK]]) | E8: 3185984 | F8: CR COIL TSBHSL LA45 2.300X1300
A9: C20 | B9: TU99 | C9: 1.4 | D9: =_xlfn.CONCAT(Table32[[#This Row],[TDC]],"-",Table32[[#This Row],[THIK]]) | E9: 2279476 | F9: CRCA COIL TSBHSQ TU99 1.400X1270
A10: C20 | B10: TU99 | C10: 1.6 | D10: =_xlfn.CONCAT(Table32[[#This Row],[TDC]],"-",Table32[[#This Row],[THIK]]) | E10: 2279503 | F10: CRCA COIL TSBHSQ TU99 1.600X1270
A11: C20 | B11: TU99 | C11: 2 | D11: =_xlfn.CONCAT(Table32[[#This Row],[TDC]],"-",Table32[[#This Row],[THIK]]) | E11: 2279483 | F11: CRCA COIL TSBHSQ TU99 2 X1270
A12: C20 | B12: TU99 | C12: 2.3 | D12: =_xlfn.CONCAT(Table32[[#This Row],[TDC]],"-",Table32[[#This Row],[THIK]]) | E12: 3439077 | F12: CR COIL TSBHSQ TU99 2.300X1270
A13: CRCA | B13: TU98 | C13: 1 | D13: =_xlfn.CONCAT(Table32[[#This Row],[TDC]],"-",Table32[[#This Row],[THIK]]) | E13: 2150938 | F13: CRCA COIL SA1008 TU98 1X1250
... A18: CRCA | B18: TU98 | C18: 1.9 | D18: =_xlfn.CONCAT(Table32[[#This Row],[TDC]],"-",Table32[[#This Row],[THIK]]) | E18: 2150943 | F18: CRCA COIL SA1008 TU98 1.900X1250
A19: CRFH | B19: RE03 | C19: 1 | D19: =_xlfn.CONCAT(Table32[[#This Row],[Grade]],"-",Table32[[#This Row],[THIK]]) | E19: 2324172 | F19: CRFH COIL TATFHC RE03 1X1250
A20: CRFH | B20: RE04 | C20: 1 | D20: =_xlfn.CONCAT(Table32[[#This Row],[Grade]],"-",Table32[[#This Row],[THIK]]) | E20: 2390551 | F20: CRFH COIL TATFHC RE04 1X1250
A21: CRFH | B21: TI15 | C21: 1 | D21: =_xlfn.CONCAT(Table32[[#This Row],[Grade]],"-",Table32[[#This Row],[THIK]]) | E21: 3917262 | F21: CR COIL TATFHC TI15 1X500
A22: CRFH | B22: TI15 | C22: 1.2 | D22: =_xlfn.CONCAT(Table32[[#This Row],[Grade]],"-",Table32[[#This Row],[THIK]]) | E22: 3917263 | F22: CR COIL TATFHC TI15 1.150X500
A23: CRFH | B23: TI15 | C23: 1.2 | D23: =_xlfn.CONCAT(Table32[[#This Row],[Grade]],"-",Table32[[#This Row],[THIK]]) | E23: 3993061 | F23: CR COIL TATFHC TI15 1.200X500
A24: CRFH | B24: RE03 | C24: 1.2 | D24: =_xlfn.CONCAT(Table32[[#This Row],[TDC]],"-",Table32[[#This Row],[THIK]]) | E24: 2324181 | F24: CRFH COIL TATFHC RE03 1.200X1250
A25: HR | B25: TU02 | C25: 1.6 | D25: =_xlfn.CONCAT(Table32[[#This Row],[TDC]],"-",Table32[[#This Row],[THIK]]) | E25: 2271033 | F25: HRPO COIL T01579 TU02 1.60X1250
A26: HR | B26: HR99 | C26: 1.9 | D26: =_xlfn.CONCAT(Table32[[#This Row],[TDC]],"-",Table32[[#This Row],[THIK]]) | E26: 3226987 | F26: HR COILS-PO THR099 HR99 1.90X1250
A27: HR | B27: TU02 | C27: 1.9 | D27: =_xlfn.CONCAT(Table32[[#This Row],[TDC]],"-",Table32[[#This Row],[THIK]]) | E27: 4141061 | F27: HR COILS-PO T01579 1.90X1250
A28: HR | B28: HR99 | C28: 2 | D28: =_xlfn.CONCAT(Table32[[#This Row],[TDC]],"-",Table32[[#This Row],[THIK]]) | E28: 1210083 | F28: HR COILS-PO THR099 HR99 2X1250
A29: HR | B29: TU02 | C29: 2 | D29: =_xlfn.CONCAT(Table32[[#This Row],[TDC]],"-",Table32[[#This Row],[THIK]]) | E29: 2427980 | F29: HRPO COIL T01579 TU02 2X1250
A30: HR | B30: HR99 | C30: 2.3 | D30: =_xlfn.CONCAT(Table32[[#This Row],[TDC]],"-",Table32[[#This Row],[THIK]]) | E30: 1371338 | F30: HR COILS-PO IS 1079 HR2 2.30X1250
A31: HR | B31: TU02 | C31: 2.3 | D31: =_xlfn.CONCAT(Table32[[#This Row],[TDC]],"-",Table32[[#This Row],[THIK]]) | E31: 3433881 | F31: HR COILS-PO T01579 TU02 2.30X1250
A32: HR | B32: HR99 | C32: 2.5 | D32: =_xlfn.CONCAT(Table32[[#This Row],[TDC]],"-",Table32[[#This Row],[THIK]]) | E32: 1250221 | F32: HR COILS-POIS 1079 HR2 2.50X1250
A33: HR | B33: TU02 | C33: 2.5 | D33: =_xlfn.CONCAT(Table32[[#This Row],[TDC]],"-",Table32[[#This Row],[THIK]]) | E33: 1706343 | F33: HRPO COIL-T01579-TU02-2.5X1250
A34: HR | B34: TU02 | C34: 2.5 | D34: =_xlfn.CONCAT(Table32[[#This Row],[TDC]],"-",Table32[[#This Row],[THIK]]) | E34: 1328020 | F34: HR COILS-PO PT 2.50X1250
A35: HR | B35: HR99 | C35: 2.9 | D35: =_xlfn.CONCAT(Table32[[#This Row],[TDC]],"-",Table32[[#This Row],[THIK]]) | E35: 1294719 | F35: HR COILS-POIS 1079 HR2 2.90X1250
... A42: HR | B42: TU02 | C42: 3.4 | D42: =_xlfn.CONCAT(Table32[[#This Row],[TDC]],"-",Table32[[#This Row],[THIK]]) | E42: 3491196 | F42: HR COILS-PO T01579 3.40X1250
B44: TI15 | C44: 1 | D44: 3917262 | E44: CR COIL TATFHC TI15 1X500 | F44: 53 | G44: 20 | H44: 29
B45: TI15 | C45: 1.15 | D45: 3917263 | E45: CR COIL TATFHC TI15 1.150X500 | F45: 5
B46: TI15 | C46: 1.2 | D46: 3993061 | E46: CR COIL TATFHC TI15 1.200X500

Sheet saleswipstock_matnos
A1: Customer | B1: Mat Nos | C1: Mat Desc | D1: OEM | E1: Bucket
A2: Metalman Auto Private Limited | B2: 4229654 | C2: CUT-R-AW-AUT-50.00X30.00X2.500X0.7650 | D2: TVS | I2: 508988 | J2: {=_xlfn.UNIQUE(I2:I2507)} | L2: {=_xlfn._xlws.FILTER(_xlfn.ANCHORARRAY(J2),ISNA(_xlfn.XMATCH(_xlfn.ANCHORARRAY(J2),buckets[Material Codes])))}
A3: ELKAYEM AUTO ANCILLARIES PRIVA | B3: 4267147 | C3: TUB-E-O-AUT-AW-FC-22.23X2.000X0.7380 | D3: TVS | I3: 1442308 | J3: 1442308
A4: Rajsriya Automotive Industries | B4: 4020858 | C4: TUB-O-N-AUT-AW-FC-25.40X2.000X0.3230 | D4: TVS | I4: 2427711 | J4: 2427711
A5: Hosur Tube Plant | B5: 3999719 | C5: CR COIL TATFHC TI15 1.150X73.50 | D5: TVS | I5: 1188598 | J5: 1188598
A6: ELKAYEM AUTO ANCILLARIES PRIVA | B6: 4185618 | C6: TUB-O-N-AUT-AW-FC-28.58X1.600X0.4200 | D6: TVS | I6: 1399341 | J6: 1399341
I7: 3729146 | J7: 3729146
I8: 3910451 | J8: 3910451
I9: 3911993 | J9: 3911993
I10: 3911993 | J10: 1241174
I11: 3911993 | J11: 3520755
I12: 3911993 | J12: 460176
I13: 3911993 | J13: 3801263
I14: 1241174 | J14: 3746291
I15: 3520755 | J15: 1938127
I16: 3911993 | J16: 2396464
I17: 3911993 | J17: 1938125
I18: 3911993 | J18: 2359755
... I266: 3935313 | J266: 3617058
I267: 4100796
I268: 4104140
I269: 3571870
I270: 3571870
I271: 3572051
I272: 3572051
I273: 3572051
I274: 3572051
I275: 3572051
I276: 3572051
I277: 3572051
I278: 3572051
... I2507: 437147

Sheet Methodology
G2: Connection | I2: Connection | K2: Connection | N2: Connection | P2: Connection | R2: Connection
G3: Sales | I3: Stock | K3: Wip | N3: Sales | P3: Stock | R3: Wip
I5: Append | P5: Append
H6: Merge | I6: Customer | O6: Merge | P6: Material Codes
G9: Table | I9: OEM_Key Different Customer | N9: Table | P9: Material Codes different

Sheet saleswipstock_customer
A1: Customer | B1: OEM

Sheet OEM_key
A1: Customer | B1: OEM | C1: CAM
A2: A.R.Automotive And Engg Industries | B2: RE | C2: Abhishek
A3: BALAJI INDUSTRIES | B3: HMSIL | C3: Abhishek
A4: BALAJI PRESS PRODUCTS INDIA | B4: TVS | C4: Apoorv
A5: BCC PIPES & TUBES PRIVATE LIMITED | B5: GE | C5: Jitendra
A6: BHARAT TUBES CORPORATION | B6: Boiler | C6: Jitendra
A7: ELKAYEM AUTO ANCILLARIES (PVT) LTD. | B7: TVS | C7: Apoorv
A8: ELKAYEM AUTO ANCILLARIES PRIVATE LI | B8: TVS | C8: Apoorv
A9: ELKAYEM AUTO ANCILLARIES PVT LTD -U | B9: TVS | C9: Apoorv
A10: GANESH INDUSTRAIL SUPPLIES | B10: Boiler | C10: Jitendra
A11: Indo Autotech Limited (Unit V) | B11: HMSIL | C11: Abhishek
A12: JBM AUTO LIMITED | B12: RE | C12: Abhishek
... A162: SHIVAMPRIME STEELS PRIVATE LIMITED | B162: GE | C162: Jitendra

Sheet Pivot_schedule
A1: SCHEDULE | B1: (Multiple Items)
A3: Sum of SCHEDULE IN MT | I3: CUSTOMER NAME | J3: CUSTOMER CODE | K3: Sum of SCHEDULE IN MT
A4: 1716.4001 | I4: Balaji press product | J4: 189287 | K4: 82.236962
I5: ELKAYEM AUTO | J5: 129663|948721 | K5: 214.57233
I6: ELKAYEM AUTO | J6: 129663|948722 | K6: 0
I7: ELKAYEM AUTO MYSORE | J7: 940921 | K7: 145.13903
I8: KAY JAY | J8: 188934 | K8: 101.62486
I9: KNITVEL NEEDLES P LTD | J9: 819045 | K9: 14.667553
I10: Marathwada | J10: 189002 | K10: 169.05631
I11: Metalman | J11: 188647 | K11: 94.862777
I12: Narasipur Auto Component(P)Ltd | J12: 187546 | K12: 64.595236
I13: Rajsriya Automotive | J13: 129695|187884|188415|189239|189240 | K13: 0
I14: Rajsriya Mysore | J14: 930883|189481 | K14: 80.680238
I15: Rajsriya Unit 1 | J15: 129695|187884|188415|189239|189240 | K15: 55.249147
I16: Rajsriya Unit 2 | J16: 129695|187884|188415|189239|189240 | K16: 44.168937
I17: Rajsriya Unit 4 | J17: 129695|187884|188415|189239|189240 | K17: 6.2978864
I18: Rajsriya Unit 5 | J18: 129663|948721 | K18: 8.6266324
I19: Rajsriya Unit 5 | J19: 129695|187884|188415|189239|189240 | K19: 79.232149
I20: Rajsriya Unit 8 | J20: 129695|187884|188415|189239|189240 | K20: 155.45208
I21: RUCHA | J21: 188534 | K21: 0
I22: Sandhar Automach | J22: 187702 | K22: 143.98859
I23: Sandhar Engg Mysore | J23: 945539 | K23: 312.52478
I24: SANDHAR ENGINEERING PVT LTD. | J24: 941496 | K24: 154.59672
I25: SRI BALAJI GEARS V4 | J25: 188595 | K25: 14.696797
I26: SRIKAM HITECH | J26: 944141 | K26: 227.02088
I27: TVS MOTOR COMPANY LIMITED | J27: 187268 | K27: 0
I28: Laxmi | J28: 185254 | K28: 43.860601
I29: SRI BALAJI GEARS V7 | J29: 188595 | K29: 186.86168
I30: Marathwada v7 | J30: 189002 | K30: 201.9446
I31: Balaji Gears V3 | J31: 188595 | K31: 15.092951
I32: NMPL TVSM | J32: 189226 | K32: 0
I33: NMPL TVSM | J33: 189226|930794 | K33: 235.78584
I34: NMPL TVSM | J34: 930801|189227 | K34: 2.267357
I35: NMPL HUB | J35: 189226|930794 | K35: 0
I36: NMPL HUB | J36: 930801|189227 | K36: 198.42091

Sheet Schedule Pivot
A3: Sum of SCHEDULE IN MT
A4: CUSTOMER NAME | B4: Total
A5: Balaji press product | B5: 82.236962
A6: ELKAYEM AUTO | B6: 214.57233
A7: ELKAYEM AUTO MYSORE | B7: 145.13903
A8: KAY JAY | B8: 101.62486
A9: KNITVEL NEEDLES P LTD | B9: 14.667553
A10: Marathwada | B10: 169.05631
A11: Metalman | B11: 94.862777
A12: Narasipur Auto Component(P)Ltd | B12: 64.595236
A13: Rajsriya Automotive | B13: 0
A14: Rajsriya Mysore | B14: 80.680238
A15: Rajsriya Unit 1 | B15: 55.249147
A16: Rajsriya Unit 2 | B16: 44.168937
... A32: NMPL HUB | B32: 198.42091

Sheet nov indent
A1: OEM | B1: Customer Code | C1: Customer | D1: Metallurgy condition | E1: Material Type | F1: GRADE | G1: OD | H1: ID | I1: THK | J1: LENGTH | K1: Length in Mtrs | L1: Key | M1: Bucket | N1: Bucket CTL | O1: plant | P1: TSL Material Code | Q1: SCH SEP- 25 | R1: BALANCE TO BE SUPPLY | S1: Stock 22-09-25 | T1: intransist | U1: OPENIG STOCK FOR NOV-2025 | V1: order logg | W1: Opening stock including order logger | X1: INDENT FOR NOV-25 as per VSM | Y1: INDENT FOR NOV-25 recommended | Z1: Before 20th | AA1: ofter 20th | AB1: Total Indent | AC1: Total Supplied | AD1: Gap
A2: TVS | B2: 943209 | C2: RUCHA | D2: ERW1 | E2: NON FIN | F2: ERW | G2: 12.7 | I2: 1.2 | J2: 6000 | K2: 6 | L2: =_xlfn.CONCAT(G2,I2,K2,F2,E2) | M2: =VLOOKUP(Table27[[#This Row],[Key]],Table29[[#All],[Key]:[TSL Material Code3]],4,0) | N2: =VLOOKUP(Table27[[#This Row],[Key]],Table29[[#All],[Key]:[TSL Material Code3]],5,0) | O2: =VLOOKUP(Table27[[#This Row],[Key]],Table29[[#All],[Key]:[TSL Material Code3]],7,0) | P2: =VLOOKUP(Table27[[#This Row],[Key]],Table29[[#All],[Key]:[TSL Material Code3]],8,0) | Q2: 10 | R2: 3 | S2: 10 | T2: 0 | U2: =S2-R2 | W2: =U2+V2 | X2: =Q2-W2 | Y2: =IF(X2>0,X2,0)*150% | Z2: =ROUND(SUMIFS(meghsteelsales_previousmonth[Quantity],meghsteelsales_previousmonth[Length Bucket],Table27[[#This Row],[Bucket CTL]])/1000,0) | AA2: =ROUND(SUMIFS(meghsteelsales_currentmonth[Quantity],meghsteelsales_currentmonth[Length Bucket],Table27[[#This Row],[Bucket CTL]])/1000,0) | AB2: =Table27[[#This Row],[ INDENT FOR NOV-25 recommended]]+Table27[[#This Row],[order logg ]] | AC2: =Table27[[#This Row],[Before 20th]]+Table27[[#This Row],[ofter 20th]] | AD2: =IF(Table27[[#This Row],[Total Indent]]-Table27[[#This Row],[Total Supplied]]<0,0,Table27[[#This Row],[Total Indent]]-Table27[[#This Row],[Total Supplied]])
A3: HMSI | B3: 943210 | C3: BADVE | D3: ERW1 | E3: NON FIN | F3: ERW | G3: 12.7 | I3: 1.4 | J3: 6000 | K3: 6 | L3: =_xlfn.CONCAT(G3,I3,K3,F3,E3) | M3: =VLOOKUP(Table27[[#This Row],[Key]],Table29[[#All],[Key]:[TSL Material Code3]],4,0) | N3: =VLOOKUP(Table27[[#This Row],[Key]],Table29[[#All],[Key]:[TSL Material Code3]],5,0) | O3: =VLOOKUP(Table27[[#This Row],[Key]],Table29[[#All],[Key]:[TSL Material Code3]],7,0) | P3: =VLOOKUP(Table27[[#This Row],[Key]],Table29[[#All],[Key]:[TSL Material Code3]],8,0) | Q3: 5 | R3: 0 | S3: 5 | T3: 0 | U3: =S3-R3 | W3: =U3+V3 | X3: =Q3-W3 | Y3: =IF(X3>0,X3,0)*150% | Z3: =ROUND(SUMIFS(meghsteelsales_previousmonth[Quantity],meghsteelsales_previousmonth[Length Bucket],Table27[[#This Row],[Bucket CTL]])/1000,0) | AA3: =ROUND(SUMIFS(meghsteelsales_currentmonth[Quantity],meghsteelsales_currentmonth[Length Bucket],Table27[[#This Row],[Bucket CTL]])/1000,0) | AB3: =Table27[[#This Row],[ INDENT FOR NOV-25 recommended]]+Table27[[#This Row],[order logg ]] | AC3: =Table27[[#This Row],[Before 20th]]+Table27[[#This Row],[ofter 20th]] | AD3: =IF(Table27[[#This Row],[Total Indent]]-Table27[[#This Row],[Total Supplied]]<0,0,Table27[[#This Row],[Total Indent]]-Table27[[#This Row],[Total Supplied]])
A4: HMSI | B4: 943210 | C4: BADVE | D4: ERW1 | E4: NON FIN | F4: ERW | G4: 12.7 | I4: 1.6 | J4: 6000 | K4: 6 | L4: =_xlfn.CONCAT(G4,I4,K4,F4,E4) | M4: =VLOOKUP(Table27[[#This Row],[Key]],Table29[[#All],[Key]:[TSL Material Code3]],4,0) | N4: =VLOOKUP(Table27[[#This Row],[Key]],Table29[[#All],[Key]:[TSL Material Code3]],5,0) | O4: =VLOOKUP(Table27[[#This Row],[Key]],Table29[[#All],[Key]:[TSL Material Code3]],7,0) | P4: =VLOOKUP(Table27[[#This Row],[Key]],Table29[[#All],[Key]:[TSL Material Code3]],8,0) | Q4: 5 | R4: 1 | S4: 3 | T4: 0 | U4: =S4-R4 | W4: =U4+V4 | X4: =Q4-W4 | Y4: =IF(X4>0,X4,0)*150% | Z4: =ROUND(SUMIFS(meghsteelsales_previousmonth[Quantity],meghsteelsales_previousmonth[Length Bucket],Table27[[#This Row],[Bucket CTL]])/1000,0) | AA4: =ROUND(SUMIFS(meghsteelsales_currentmonth[Quantity],meghsteelsales_currentmonth[Length Bucket],Table27[[#This Row],[Bucket CTL]])/1000,0) | AB4: =Table27[[#This Row],[ INDENT FOR NOV-25 recommended]]+Table27[[#This Row],[order logg ]] | AC4: =Table27[[#This Row],[Before 20th]]+Table27[[#This Row],[ofter 20th]] | AD4: =IF(Table27[[#This Row],[Total Indent]]-Table27[[#This Row],[Total Supplied]]<0,0,Table27[[#This Row],[Total Indent]]-Table27[[#This Row],[Total Supplied]])
A5: HMSI | B5: 943210 | C5: BADVE | D5: ERW1 | E5: NON FIN | F5: ERW | G5: 15.88 | I5: 1 | J5: 6000 | K5: 6 | L5: =_xlfn.CONCAT(G5,I5,K5,F5,E5) | M5: =VLOOKUP(Table27[[#This Row],[Key]],Table29[[#All],[Key]:[TSL Material Code3]],4,0) | N5: =VLOOKUP(Table27[[#This Row],[Key]],Table29[[#All],[Key]:[TSL Material Code3]],5,0) | O5: =VLOOKUP(Table27[[#This Row],[Key]],Table29[[#All],[Key]:[TSL Material Code3]],7,0) | P5: =VLOOKUP(Table27[[#This Row],[Key]],Table29[[#All],[Key]:[TSL Material Code3]],8,0) | Q5: 1 | R5: 0 | S5: 1.4 | T5: 0 | U5: =S5-R5 | W5: =U5+V5 | X5: =Q5-W5 | Y5: =IF(X5>0,X5,0)*150% | Z5: =ROUND(SUMIFS(meghsteelsales_previousmonth[Quantity],meghsteelsales_previousmonth[Length Bucket],Table27[[#This Row],[Bucket CTL]])/1000,0) | AA5: =ROUND(SUMIFS(meghsteelsales_currentmonth[Quantity],meghsteelsales_currentmonth[Length Bucket],Table27[[#This Row],[Bucket CTL]])/1000,0) | AB5: =Table27[[#This Row],[ INDENT FOR NOV-25 recommended]]+Table27[[#This Row],[order logg ]] | AC5: =Table27[[#This Row],[Before 20th]]+Table27[[#This Row],[ofter 20th]] | AD5: =IF(Table27[[#This Row],[Total Indent]]-Table27[[#This Row],[Total Supplied]]<0,0,Table27[[#This Row],[Total Indent]]-Table27[[#This Row],[Total Supplied]])
A6: TVS | B6: 943209 | C6: RUCHA | D6: ERW1 | E6: NON FIN | F6: ERW | G6: 15.88 | I6: 1.2 | J6: 6000 | K6: 6 | L6: =_xlfn.CONCAT(G6,I6,K6,F6,E6) | M6: =VLOOKUP(Table27[[#This Row],[Key]],Table29[[#All],[Key]:[TSL Material Code3]],4,0) | N6: =VLOOKUP(Table27[[#This Row],[Key]],Table29[[#All],[Key]:[TSL Material Code3]],5,0) | O6: =VLOOKUP(Table27[[#This Row],[Key]],Table29[[#All],[Key]:[TSL Material Code3]],7,0) | P6: =VLOOKUP(Table27[[#This Row],[Key]],Table29[[#All],[Key]:[TSL Material Code3]],8,0) | Q6: 8 | R6: 4 | S6: 22.4 | T6: 0 | U6: =S6-R6 | W6: =U6+V6 | X6: =Q6-W6 | Y6: =IF(X6>0,X6,0)*150% | Z6: =ROUND(SUMIFS(meghsteelsales_previousmonth[Quantity],meghsteelsales_previousmonth[Length Bucket],Table27[[#This Row],[Bucket CTL]])/1000,0) | AA6: =ROUND(SUMIFS(meghsteelsales_currentmonth[Quantity],meghsteelsales_currentmonth[Length Bucket],Table27[[#This Row],[Bucket CTL]])/1000,0) | AB6: =Table27[[#This Row],[ INDENT FOR NOV-25 recommended]]+Table27[[#This Row],[order logg ]] | AC6: =Table27[[#This Row],[Before 20th]]+Table27[[#This Row],[ofter 20th]] | AD6: =IF(Table27[[#This Row],[Total Indent]]-Table27[[#This Row],[Total Supplied]]<0,0,Table27[[#This Row],[Total Indent]]-Table27[[#This Row],[Total Supplied]])
A7: HMSI | B7: 943210 | C7: BADVE | D7: ERW1 | E7: NON FIN | F7: ERW | G7: 15.88 | I7: 1.6 | J7: 6000 | K7: 6 | L7: =_xlfn.CONCAT(G7,I7,K7,F7,E7) | M7: =VLOOKUP(Table27[[#This Row],[Key]],Table29[[#All],[Key]:[TSL Material Code3]],4,0) | N7: =VLOOKUP(Table27[[#This Row],[Key]],Table29[[#All],[Key]:[TSL Material Code3]],5,0) | O7: =VLOOKUP(Table27[[#This Row],[Key]],Table29[[#All],[Key]:[TSL Material Code3]],7,0) | P7: =VLOOKUP(Table27[[#This Row],[Key]],Table29[[#All],[Key]:[TSL Material Code3]],8,0) | Q7: 5 | R7: 2 | S7: 0.5 | T7: 2.75 | U7: =S7-R7 | W7: =U7+V7 | X7: =Q7-W7 | Y7: =IF(X7>0,X7,0)*150% | Z7: =ROUND(SUMIFS(meghsteelsales_previousmonth[Quantity],meghsteelsales_previousmonth[Length Bucket],Table27[[#This Row],[Bucket CTL]])/1000,0) | AA7: =ROUND(SUMIFS(meghsteelsales_currentmonth[Quantity],meghsteelsales_currentmonth[Length Bucket],Table27[[#This Row],[Bucket CTL]])/1000,0) | AB7: =Table27[[#This Row],[ INDENT FOR NOV-25 recommended]]+Table27[[#This Row],[order logg ]] | AC7: =Table27[[#This Row],[Before 20th]]+Table27[[#This Row],[ofter 20th]] | AD7: =IF(Table27[[#This Row],[Total Indent]]-Table27[[#This Row],[Total Supplied]]<0,0,Table27[[#This Row],[Total Indent]]-Table27[[#This Row],[Total Supplied]])
A8: HMSI | B8: 943210 | C8: BADVE | D8: ERW1 | E8: NON FIN | F8: ERW | G8: 15.88 | I8: 2 | J8: 6000 | K8: 6 | L8: =_xlfn.CONCAT(G8,I8,K8,F8,E8) | M8: =VLOOKUP(Table27[[#This Row],[Key]],Table29[[#All],[Key]:[TSL Material Code3]],4,0) | N8: =VLOOKUP(Table27[[#This Row],[Key]],Table29[[#All],[Key]:[TSL Material Code3]],5,0) | O8: =VLOOKUP(Table27[[#This Row],[Key]],Table29[[#All],[Key]:[TSL Material Code3]],7,0) | P8: =VLOOKUP(Table27[[#This Row],[Key]],Table29[[#All],[Key]:[TSL Material Code3]],8,0) | Q8: 5 | R8: 1 | S8: 10 | T8: 0 | U8: =S8-R8 | W8: =U8+V8 | X8: =Q8-W8 | Y8: =IF(X8>0,X8,0)*150% | Z8: =ROUND(SUMIFS(meghsteelsales_previousmonth[Quantity],meghsteelsales_previousmonth[Length Bucket],Table27[[#This Row],[Bucket CTL]])/1000,0) | AA8: =ROUND(SUMIFS(meghsteelsales_currentmonth[Quantity],meghsteelsales_currentmonth[Length Bucket],Table27[[#This Row],[Bucket CTL]])/1000,0) | AB8: =Table27[[#This Row],[ INDENT FOR NOV-25 recommended]]+Table27[[#This Row],[order logg ]] | AC8: =Table27[[#This Row],[Before 20th]]+Table27[[#This Row],[ofter 20th]] | AD8: =IF(Table27[[#This Row],[Total Indent]]-Table27[[#This Row],[Total Supplied]]<0,0,Table27[[#This Row],[Total Indent]]-Table27[[#This Row],[Total Supplied]])
A9: TVS | B9: 943209 | C9: Rucha | D9: ERW1 | E9: NON FIN | F9: ERW | G9: 18.2 | I9: 1 | J9: 6000 | K9: 6 | L9: =_xlfn.CONCAT(G9,I9,K9,F9,E9) | M9: =VLOOKUP(Table27[[#This Row],[Key]],Table29[[#All],[Key]:[TSL Material Code3]],4,0) | N9: =VLOOKUP(Table27[[#This Row],[Key]],Table29[[#All],[Key]:[TSL Material Code3]],5,0) | O9: =VLOOKUP(Table27[[#This Row],[Key]],Table29[[#All],[Key]:[TSL Material Code3]],7,0) | P9: =VLOOKUP(Table27[[#This Row],[Key]],Table29[[#All],[Key]:[TSL Material Code3]],8,0) | Q9: 10 | R9: 5 | S9: 8.8 | T9: 0 | U9: =S9-R9 | W9: =U9+V9 | X9: =Q9-W9 | Y9: =IF(X9>0,X9,0)*150% | Z9: =ROUND(SUMIFS(meghsteelsales_previousmonth[Quantity],meghsteelsales_previousmonth[Length Bucket],Table27[[#This Row],[Bucket CTL]])/1000,0) | AA9: =ROUND(SUMIFS(meghsteelsales_currentmonth[Quantity],meghsteelsales_currentmonth[Length Bucket],Table27[[#This Row],[Bucket CTL]])/1000,0) | AB9: =Table27[[#This Row],[ INDENT FOR NOV-25 recommended]]+Table27[[#This Row],[order logg ]] | AC9: =Table27[[#This Row],[Before 20th]]+Table27[[#This Row],[ofter 20th]] | AD9: =IF(Table27[[#This Row],[Total Indent]]-Table27[[#This Row],[Total Supplied]]<0,0,Table27[[#This Row],[Total Indent]]-Table27[[#This Row],[Total Supplied]])
A10: HMSI | B10: 943210 | C10: BADVE | D10: ERW1 | E10: NON FIN | F10: ERW | G10: 19.05 | I10: 1.6 | J10: 6000 | K10: 6 | L10: =_xlfn.CONCAT(G10,I10,K10,F10,E10) | M10: =VLOOKUP(Table27[[#This Row],[Key]],Table29[[#All],[Key]:[TSL Material Code3]],4,0) | N10: =VLOOKUP(Table27[[#This Row],[Key]],Table29[[#All],[Key]:[TSL Material Code3]],5,0) | O10: =VLOOKUP(Table27[[#This Row],[Key]],Table29[[#All],[Key]:[TSL Material Code3]],7,0) | P10: =VLOOKUP(Table27[[#This Row],[Key]],Table29[[#All],[Key]:[TSL Material Code3]],8,0) | Q10: 10 | R10: 5 | S10: 14 | T10: 0 | U10: =S10-R10 | V10: 2.7 | W10: =U10+V10 | X10: =Q10-W10 | Y10: =IF(X10>0,X10,0)*150% | Z10: =ROUND(SUMIFS(meghsteelsales_previousmonth[Quantity],meghsteelsales_previousmonth[Length Bucket],Table27[[#This Row],[Bucket CTL]])/1000,0) | AA10: =ROUND(SUMIFS(meghsteelsales_currentmonth[Quantity],meghsteelsales_currentmonth[Length Bucket],Table27[[#This Row],[Bucket CTL]])/1000,0) | AB10: =Table27[[#This Row],[ INDENT FOR NOV-25 recommended]]+Table27[[#This Row],[order logg ]] | AC10: =Table27[[#This Row],[Before 20th]]+Table27[[#This Row],[ofter 20th]] | AD10: =IF(Table27[[#This Row],[Total Indent]]-Table27[[#This Row],[Total Supplied]]<0,0,Table27[[#This Row],[Total Indent]]-Table27[[#This Row],[Total Supplied]])
A11: HMSI | B11: 943210 | C11: BADVE | D11: ERW2 | E11: NON FIN | F11: ERW2 | G11: 19.05 | I11: 1.4 | J11: 6000 | K11: 6 | L11: =_xlfn.CONCAT(G11,I11,K11,F11,E11) | M11: =VLOOKUP(Table27[[#This Row],[Key]],Table29[[#All],[Key]:[TSL Material Code3]],4,0) | N11: =VLOOKUP(Table27[[#This Row],[Key]],Table29[[#All],[Key]:[TSL Material Code3]],5,0) | O11: =VLOOKUP(Table27[[#This Row],[Key]],Table29[[#All],[Key]:[TSL Material Code3]],7,0) | P11: =VLOOKUP(Table27[[#This Row],[Key]],Table29[[#All],[Key]:[TSL Material Code3]],8,0) | Q11: 10 | R11: 3 | S11: 0 | T11: 0 | U11: =S11-R11 | V11: 10 | W11: =U11+V11 | X11: =Q11-W11 | Y11: =IF(X11>0,X11,0)*150% | Z11: =ROUND(SUMIFS(meghsteelsales_previousmonth[Quantity],meghsteelsales_previousmonth[Length Bucket],Table27[[#This Row],[Bucket CTL]])/1000,0) | AA11: =ROUND(SUMIFS(meghsteelsales_currentmonth[Quantity],meghsteelsales_currentmonth[Length Bucket],Table27[[#This Row],[Bucket CTL]])/1000,0) | AB11: =Table27[[#This Row],[ INDENT FOR NOV-25 recommended]]+Table27[[#This Row],[order logg ]] | AC11: =Table27[[#This Row],[Before 20th]]+Table27[[#This Row],[ofter 20th]] | AD11: =IF(Table27[[#This Row],[Total Indent]]-Table27[[#This Row],[Total Supplied]]<0,0,Table27[[#This Row],[Total Indent]]-Table27[[#This Row],[Total Supplied]])
A12: TVS | B12: 943209 | C12: RUCHA | D12: ERW1 | E12: NON FIN | F12: ERW | G12: 19.05 | I12: 2 | J12: 5800 | K12: 5.8 | L12: =_xlfn.CONCAT(G12,I12,K12,F12,E12) | M12: =VLOOKUP(Table27[[#This Row],[Key]],Table29[[#All],[Key]:[TSL Material Code3]],4,0) | N12: =VLOOKUP(Table27[[#This Row],[Key]],Table29[[#All],[Key]:[TSL Material Code3]],5,0) | O12: 0789 | P12: =VLOOKUP(Table27[[#This Row],[Key]],Table29[[#All],[Key]:[TSL Material Code3]],8,0) | Q12: 35 | R12: 10 | S12: 6 | T12: 0 | U12: 0 | W12: =U12+V12 | X12: =Q12-W12 | Y12: =IF(X12>0,X12,0)*150% | Z12: =ROUND(SUMIFS(meghsteelsales_previousmonth[Quantity],meghsteelsales_previousmonth[Length Bucket],Table27[[#This Row],[Bucket CTL]])/1000,0) | AA12: =ROUND(SUMIFS(meghsteelsales_currentmonth[Quantity],meghsteelsales_currentmonth[Length Bucket],Table27[[#This Row],[Bucket CTL]])/1000,0) | AB12: =Table27[[#This Row],[ INDENT FOR NOV-25 recommended]]+Table27[[#This Row],[order logg ]] | AC12: =Table27[[#This Row],[Before 20th]]+Table27[[#This Row],[ofter 20th]] | AD12: =IF(Table27[[#This Row],[Total Indent]]-Table27[[#This Row],[Total Supplied]]<0,0,Table27[[#This Row],[Total Indent]]-Table27[[#This Row],[Total Supplied]])
A13: TVS | B13: 943209 | C13: RUCHA,METALMAN | D13: ERW1 | E13: NON FIN | F13: ERW | G13: 19.05 | I13: 2.3 | J13: 7000 | K13: 7 | L13: =_xlfn.CONCAT(G13,I13,K13,F13,E13) | M13: =VLOOKUP(Table27[[#This Row],[Key]],Table29[[#All],[Key]:[TSL Material Code3]],4,0) | N13: =VLOOKUP(Table27[[#This Row],[Key]],Table29[[#All],[Key]:[TSL Material Code3]],5,0) | O13: =VLOOKUP(Table27[[#This Row],[Key]],Table29[[#All],[Key]:[TSL Material Code3]],7,0) | P13: =VLOOKUP(Table27[[#This Row],[Key]],Table29[[#All],[Key]:[TSL Material Code3]],8,0) | Q13: 20 | R13: 10 | S13: 39 | T13: 0 | U13: =S13-R13 | W13: =U13+V13 | X13: =Q13-W13 | Y13: =IF(X13>0,X13,0)*150% | Z13: =ROUND(SUMIFS(meghsteelsales_previousmonth[Quantity],meghsteelsales_previousmonth[Length Bucket],Table27[[#This Row],[Bucket CTL]])/1000,0) | AA13: =ROUND(SUMIFS(meghsteelsales_currentmonth[Quantity],meghsteelsales_currentmonth[Length Bucket],Table27[[#This Row],[Bucket CTL]])/1000,0) | AB13: =Table27[[#This Row],[ INDENT FOR NOV-25 recommended]]+Table27[[#This Row],[order logg ]] | AC13: =Table27[[#This Row],[Before 20th]]+Table27[[#This Row],[ofter 20th]] | AD13: =IF(Table27[[#This Row],[Total Indent]]-Table27[[#This Row],[Total Supplied]]<0,0,Table27[[#This Row],[Total Indent]]-Table27[[#This Row],[Total Supplied]])
A14: TVS | B14: 943209 | C14: RUCHA | D14: ERW1 | E14: NON FIN | F14: ERW | G14: 21.4 | I14: 1.6 | J14: 6000 | K14: 6 | L14: =_xlfn.CONCAT(G14,I14,K14,F14,E14) | M14: =VLOOKUP(Table27[[#This Row],[Key]],Table29[[#All],[Key]:[TSL Material Code3]],4,0) | N14: =VLOOKUP(Table27[[#This Row],[Key]],Table29[[#All],[Key]:[TSL Material Code3]],5,0) | O14: =VLOOKUP(Table27[[#This Row],[Key]],Table29[[#All],[Key]:[TSL Material Code3]],7,0) | P14: =VLOOKUP(Table27[[#This Row],[Key]],Table29[[#All],[Key]:[TSL Material Code3]],8,0) | Q14: 10 | R14: 3 | S14: 14.3 | T14: 0 | U14: =S14-R14 | W14: =U14+V14 | X14: =Q14-W14 | Y14: =IF(X14>0,X14,0)*150% | Z14: =ROUND(SUMIFS(meghsteelsales_previousmonth[Quantity],meghsteelsales_previousmonth[Length Bucket],Table27[[#This Row],[Bucket CTL]])/1000,0) | AA14: =ROUND(SUMIFS(meghsteelsales_currentmonth[Quantity],meghsteelsales_currentmonth[Length Bucket],Table27[[#This Row],[Bucket CTL]])/1000,0) | AB14: =Table27[[#This Row],[ INDENT FOR NOV-25 recommended]]+Table27[[#This Row],[order logg ]] | AC14: =Table27[[#This Row],[Before 20th]]+Table27[[#This Row],[ofter 20th]] | AD14: =IF(Table27[[#This Row],[Total Indent]]-Table27[[#This Row],[Total Supplied]]<0,0,Table27[[#This Row],[Total Indent]]-Table27[[#This Row],[Total Supplied]])
A15: TVS | B15: 943209 | C15: RUCHA | D15: ERW1 | E15: NON FIN | F15: ERW | G15: 22.2 | I15: 1.2 | J15: 5870 | K15: 5.87 | L15: =_xlfn.CONCAT(G15,I15,K15,F15,E15) | M15: =VLOOKUP(Table27[[#This Row],[Key]],Table29[[#All],[Key]:[TSL Material Code3]],4,0) | N15: =VLOOKUP(Table27[[#This Row],[Key]],Table29[[#All],[Key]:[TSL Material Code3]],5,0) | O15: =VLOOKUP(Table27[[#This Row],[Key]],Table29[[#All],[Key]:[TSL Material Code3]],7,0) | P15: =VLOOKUP(Table27[[#This Row],[Key]],Table29[[#All],[Key]:[TSL Material Code3]],8,0) | Q15: 30 | R15: 10 | S15: 7 | T15: 15.8 | U15: =S15-R15 | V15: 6 | W15: =U15+V15 | X15: =Q15-W15 | Y15: =IF(X15>0,X15,0)*150% | Z15: =ROUND(SUMIFS(meghsteelsales_previousmonth[Quantity],meghsteelsales_previousmonth[Length Bucket],Table27[[#This Row],[Bucket CTL]])/1000,0) | AA15: =ROUND(SUMIFS(meghsteelsales_currentmonth[Quantity],meghsteelsales_currentmonth[Length Bucket],Table27[[#This Row],[Bucket CTL]])/1000,0) | AB15: =Table27[[#This Row],[ INDENT FOR NOV-25 recommended]]+Table27[[#This Row],[order logg ]] | AC15: =Table27[[#This Row],[Before 20th]]+Table27[[#This Row],[ofter 20th]] | AD15: =IF(Table27[[#This Row],[Total Indent]]-Table27[[#This Row],[Total Supplied]]<0,0,Table27[[#This Row],[Total Indent]]-Table27[[#This Row],[Total Supplied]])
A16: HMSI | B16: 943210 | C16: BADVE | D16: ERW2 | E16: NON FIN | F16: ERW-2 | G16: 22.2 | I16: 1.4 | J16: 6000 | K16: 6 | L16: =_xlfn.CONCAT(G16,I16,K16,F16,E16) | M16: =VLOOKUP(Table27[[#This Row],[Key]],Table29[[#All],[Key]:[TSL Material Code3]],4,0) | N16: =VLOOKUP(Table27[[#This Row],[Key]],Table29[[#All],[Key]:[TSL Material Code3]],5,0) | O16: =VLOOKUP(Table27[[#This Row],[Key]],Table29[[#All],[Key]:[TSL Material Code3]],7,0) | P16: =VLOOKUP(Table27[[#This Row],[Key]],Table29[[#All],[Key]:[TSL Material Code3]],8,0) | Q16: 10 | R16: 3 | S16: 19 | T16: 0 | U16: =S16-R16 | W16: =U16+V16 | X16: =Q16-W16 | Y16: =IF(X16>0,X16,0)*150% | Z16: =ROUND(SUMIFS(meghsteelsales_previousmonth[Quantity],meghsteelsales_previousmonth[Length Bucket],Table27[[#This Row],[Bucket CTL]])/1000,0) | AA16: =ROUND(SUMIFS(meghsteelsales_currentmonth[Quantity],meghsteelsales_currentmonth[Length Bucket],Table27[[#This Row],[Bucket CTL]])/1000,0) | AB16: =Table27[[#This Row],[ INDENT FOR NOV-25 recommended]]+Table27[[#This Row],[order logg ]] | AC16: =Table27[[#This Row],[Before 20th]]+Table27[[#This Row],[ofter 20th]] | AD16: =IF(Table27[[#This Row],[Total Indent]]-Table27[[#This Row],[Total Supplied]]<0,0,Table27[[#This Row],[Total Indent]]-Table27[[#This Row],[Total Supplied]])
A17: TVS | B17: 943209 | C17: RUCHA | D17: ERW1 | E17: NON FIN | F17: ERW | G17: 22.2 | I17: 1.6 | J17: 5270 | K17: 5.27 | L17: =_xlfn.CONCAT(G17,I17,K17,F17,E17) | M17: =VLOOKUP(Table27[[#This Row],[Key]],Table29[[#All],[Key]:[TSL Material Code3]],4,0) | N17: =VLOOKUP(Table27[[#This Row],[Key]],Table29[[#All],[Key]:[TSL Material Code3]],5,0) | O17: =VLOOKUP(Table27[[#This Row],[Key]],Table29[[#All],[Key]:[TSL Material Code3]],7,0) | P17: =VLOOKUP(Table27[[#This Row],[Key]],Table29[[#All],[Key]:[TSL Material Code3]],8,0) | Q17: 30 | R17: 15 | S17: 5 | T17: 0 | U17: =S17-R17 | W17: =U17+V17 | X17: =Q17-W17 | Y17: =IF(X17>0,X17,0)*150% | Z17: =ROUND(SUMIFS(meghsteelsales_previousmonth[Quantity],meghsteelsales_previousmonth[Length Bucket],Table27[[#This Row],[Bucket CTL]])/1000,0) | AA17: =ROUND(SUMIFS(meghsteelsales_currentmonth[Quantity],meghsteelsales_currentmonth[Length Bucket],Table27[[#This Row],[Bucket CTL]])/1000,0) | AB17: =Table27[[#This Row],[ INDENT FOR NOV-25 recommended]]+Table27[[#This Row],[order logg ]] | AC17: =Table27[[#This Row],[Before 20th]]+Table27[[#This Row],[ofter 20th]] | AD17: =IF(Table27[[#This Row],[Total Indent]]-Table27[[#This Row],[Total Supplied]]<0,0,Table27[[#This Row],[Total Indent]]-Table27[[#This Row],[Total Supplied]])
A18: TVS | B18: 943209 | C18: RUCHA | D18: ERW1 | E18: NON FIN | F18: ERW | G18: 22.2 | I18: 1.6 | J18: 5670 | K18: 5.67 | L18: =_xlfn.CONCAT(G18,I18,K18,F18,E18) | M18: =VLOOKUP(Table27[[#This Row],[Key]],Table29[[#All],[Key]:[TSL Material Code3]],4,0) | N18: =VLOOKUP(Table27[[#This Row],[Key]],Table29[[#All],[Key]:[TSL Material Code3]],5,0) | O18: =VLOOKUP(Table27[[#This Row],[Key]],Table29[[#All],[Key]:[TSL Material Code3]],7,0) | P18: =VLOOKUP(Table27[[#This Row],[Key]],Table29[[#All],[Key]:[TSL Material Code3]],8,0) | Q18: 30 | R18: 10 | S18: 25.6 | T18: 0 | U18: =S18-R18 | W18: =U18+V18 | X18: =Q18-W18 | Y18: =IF(X18>0,X18,0)*150% | Z18: =ROUND(SUMIFS(meghsteelsales_previousmonth[Quantity],meghsteelsales_previousmonth[Length Bucket],Table27[[#This Row],[Bucket CTL]])/1000,0) | AA18: =ROUND(SUMIFS(meghsteelsales_currentmonth[Quantity],meghsteelsales_currentmonth[Length Bucket],Table27[[#This Row],[Bucket CTL]])/1000,0) | AB18: =Table27[[#This Row],[ INDENT FOR NOV-25 recommended]]+Table27[[#This Row],[order logg ]] | AC18: =Table27[[#This Row],[Before 20th]]+Table27[[#This Row],[ofter 20th]] | AD18: =IF(Table27[[#This Row],[Total Indent]]-Table27[[#This Row],[Total Supplied]]<0,0,Table27[[#This Row],[Total Indent]]-Table27[[#This Row],[Total Supplied]])
A19: TVS | B19: 943209 | C19: RUCHA | D19: ERW1 | E19: NON FIN | F19: ERW | G19: 22.2 | I19: 2 | J19: 5950 | K19: 5.95 | L19: =_xlfn.CONCAT(G19,I19,K19,F19,E19) | M19: =VLOOKUP(Table27[[#This Row],[Key]],Table29[[#All],[Key]:[TSL Material Code3]],4,0) | N19: =VLOOKUP(Table27[[#This Row],[Key]],Table29[[#All],[Key]:[TSL Material Code3]],5,0) | O19: =VLOOKUP(Table27[[#This Row],[Key]],Table29[[#All],[Key]:[TSL Material Code3]],7,0) | P19: =VLOOKUP(Table27[[#This Row],[Key]],Table29[[#All],[Key]:[TSL Material Code3]],8,0) | Q19: 80 | R19: 30 | S19: 5.8 | T19: 0 | U19: =S19-R19 | V19: 46.6 | W19: =U19+V19 | X19: =Q19-W19 | Y19: =IF(X19>0,X19,0)*150% | Z19: =ROUND(SUMIFS(meghsteelsales_previousmonth[Quantity],meghsteelsales_previousmonth[Length Bucket],Table27[[#This Row],[Bucket CTL]])/1000,0) | AA19: =ROUND(SUMIFS(meghsteelsales_currentmonth[Quantity],meghsteelsales_currentmonth[Length Bucket],Table27[[#This Row],[Bucket CTL]])/1000,0) | AB19: =Table27[[#This Row],[ INDENT FOR NOV-25 recommended]]+Table27[[#This Row],[order logg ]] | AC19: =Table27[[#This Row],[Before 20th]]+Table27[[#This Row],[ofter 20th]] | AD19: =IF(Table27[[#This Row],[Total Indent]]-Table27[[#This Row],[Total Supplied]]<0,0,Table27[[#This Row],[Total Indent]]-Table27[[#This Row],[Total Supplied]])
A20: TVS | B20: 943209 | C20: RUCHA | D20: ERW1 | E20: NON FIN | F20: ERW | G20: 22.2 | I20: 2 | J20: 5100 | K20: 5.1 | L20: =_xlfn.CONCAT(G20,I20,K20,F20,E20) | M20: =VLOOKUP(Table27[[#This Row],[Key]],Table29[[#All],[Key]:[TSL Material Code3]],4,0) | N20: =VLOOKUP(Table27[[#This Row],[Key]],Table29[[#All],[Key]:[TSL Material Code3]],5,0) | O20: =VLOOKUP(Table27[[#This Row],[Key]],Table29[[#All],[Key]:[TSL Material Code3]],7,0) | P20: =VLOOKUP(Table27[[#This Row],[Key]],Table29[[#All],[Key]:[TSL Material Code3]],8,0) | Q20: 20 | R20: 5 | S20: 19 | T20: 0 | U20: =S20-R20 | V20: 7 | W20: =U20+V20 | X20: =Q20-W20 | Y20: =IF(X20>0,X20,0)*150% | Z20: =ROUND(SUMIFS(meghsteelsales_previousmonth[Quantity],meghsteelsales_previousmonth[Length Bucket],Table27[[#This Row],[Bucket CTL]])/1000,0) | AA20: =ROUND(SUMIFS(meghsteelsales_currentmonth[Quantity],meghsteelsales_currentmonth[Length Bucket],Table27[[#This Row],[Bucket CTL]])/1000,0) | AB20: =Table27[[#This Row],[ INDENT FOR NOV-25 recommended]]+Table27[[#This Row],[order logg ]] | AC20: =Table27[[#This Row],[Before 20th]]+Table27[[#This Row],[ofter 20th]] | AD20: =IF(Table27[[#This Row],[Total Indent]]-Table27[[#This Row],[Total Supplied]]<0,0,Table27[[#This Row],[Total Indent]]-Table27[[#This Row],[Total Supplied]])
A21: TVS | B21: 943209 | C21: RUCHA | D21: ERW2 | E21: FIN CUT | F21: HST | G21: 22.2 | I21: 2 | J21: 6000 | K21: 6000 | L21: =_xlfn.CONCAT(G21,I21,K21,F21,E21) | M21: =VLOOKUP(Table27[[#This Row],[Key]],Table29[[#All],[Key]:[TSL Material Code3]],4,0) | N21: =VLOOKUP(Table27[[#This Row],[Key]],Table29[[#All],[Key]:[TSL Material Code3]],5,0) | O21: =VLOOKUP(Table27[[#This Row],[Key]],Table29[[#All],[Key]:[TSL Material Code3]],7,0) | P21: =VLOOKUP(Table27[[#This Row],[Key]],Table29[[#All],[Key]:[TSL Material Code3]],8,0) | Q21: 40 | R21: 15 | S21: 57 | T21: 0 | U21: =S21-R21 | W21: =U21+V21 | X21: =Q21-W21 | Y21: =IF(X21>0,X21,0)*150% | Z21: =ROUND(SUMIFS(meghsteelsales_previousmonth[Quantity],meghsteelsales_previousmonth[Length Bucket],Table27[[#This Row],[Bucket CTL]])/1000,0) | AA21: =ROUND(SUMIFS(meghsteelsales_currentmonth[Quantity],meghsteelsales_currentmonth[Length Bucket],Table27[[#This Row],[Bucket CTL]])/1000,0) | AB21: =Table27[[#This Row],[ INDENT FOR NOV-25 recommended]]+Table27[[#This Row],[order logg ]] | AC21: =Table27[[#This Row],[Before 20th]]+Table27[[#This Row],[ofter 20th]] | AD21: =IF(Table27[[#This Row],[Total Indent]]-Table27[[#This Row],[Total Supplied]]<0,0,Table27[[#This Row],[Total Indent]]-Table27[[#This Row],[Total Supplied]])
A22: HMSI | B22: 943210 | C22: BADVE | D22: CR ERW 1 | E22: FIN CUT | F22: CR ERW | G22: 22.2 | I22: 2 | J22: 5390 | K22: 5.39 | L22: =_xlfn.CONCAT(G22,I22,K22,F22,E22) | M22: =VLOOKUP(Table27[[#This Row],[Key]],Table29[[#All],[Key]:[TSL Material Code3]],4,0) | N22: =VLOOKUP(Table27[[#This Row],[Key]],Table29[[#All],[Key]:[TSL Material Code3]],5,0) | O22: =VLOOKUP(Table27[[#This Row],[Key]],Table29[[#All],[Key]:[TSL Material Code3]],7,0) | P22: =VLOOKUP(Table27[[#This Row],[Key]],Table29[[#All],[Key]:[TSL Material Code3]],8,0) | Q22: 10 | R22: 5 | S22: 0 | T22: 0 | U22: =S22-R22 | W22: =U22+V22 | X22: =Q22-W22 | Y22: =IF(X22>0,X22,0)*150% | Z22: =ROUND(SUMIFS(meghsteelsales_previousmonth[Quantity],meghsteelsales_previousmonth[Length Bucket],Table27[[#This Row],[Bucket CTL]])/1000,0) | AA22: =ROUND(SUMIFS(meghsteelsales_currentmonth[Quantity],meghsteelsales_currentmonth[Length Bucket],Table27[[#This Row],[Bucket CTL]])/1000,0) | AB22: =Table27[[#This Row],[ INDENT FOR NOV-25 recommended]]+Table27[[#This Row],[order logg ]] | AC22: =Table27[[#This Row],[Before 20th]]+Table27[[#This Row],[ofter 20th]] | AD22: =IF(Table27[[#This Row],[Total Indent]]-Table27[[#This Row],[Total Supplied]]<0,0,Table27[[#This Row],[Total Indent]]-Table27[[#This Row],[Total Supplied]])
A23: HMSI | B23: 943210 | C23: BADVE | D23: ERW2 | E23: FIN CUT | F23: HST | G23: 25.4 | I23: 1.4 | J23: 5531 | K23: 5.531 | L23: =_xlfn.CONCAT(G23,I23,K23,F23,E23) | M23: =VLOOKUP(Table27[[#This Row],[Key]],Table29[[#All],[Key]:[TSL Material Code3]],4,0) | N23: =VLOOKUP(Table27[[#This Row],[Key]],Table29[[#All],[Key]:[TSL Material Code3]],5,0) | O23: =VLOOKUP(Table27[[#This Row],[Key]],Table29[[#All],[Key]:[TSL Material Code3]],7,0) | P23: =VLOOKUP(Table27[[#This Row],[Key]],Table29[[#All],[Key]:[TSL Material Code3]],8,0) | Q23: 15 | R23: 0 | S23: 0 | T23: 0 | U23: =S23-R23 | V23: 16 | W23: =U23+V23 | X23: =Q23-W23 | Y23: =IF(X23>0,X23,0)*150% | Z23: =ROUND(SUMIFS(meghsteelsales_previousmonth[Quantity],meghsteelsales_previousmonth[Length Bucket],Table27[[#This Row],[Bucket CTL]])/1000,0) | AA23: =ROUND(SUMIFS(meghsteelsales_currentmonth[Quantity],meghsteelsales_currentmonth[Length Bucket],Table27[[#This Row],[Bucket CTL]])/1000,0) | AB23: =Table27[[#This Row],[ INDENT FOR NOV-25 recommended]]+Table27[[#This Row],[order logg ]] | AC23: =Table27[[#This Row],[Before 20th]]+Table27[[#This Row],[ofter 20th]] | AD23: =IF(Table27[[#This Row],[Total Indent]]-Table27[[#This Row],[Total Supplied]]<0,0,Table27[[#This Row],[Total Indent]]-Table27[[#This Row],[Total Supplied]])
A24: HMSI | B24: 943210 | C24: BADVE | D24: ERW1 | E24: FIN CUT | F24: ERW | G24: 25.4 | I24: 1.4 | J24: 6060 | K24: 6.06 | L24: =_xlfn.CONCAT(G24,I24,K24,F24,E24) | M24: =VLOOKUP(Table27[[#This Row],[Key]],Table29[[#All],[Key]:[TSL Material Code3]],4,0) | N24: =VLOOKUP(Table27[[#This Row],[Key]],Table29[[#All],[Key]:[TSL Material Code3]],5,0) | O24: =VLOOKUP(Table27[[#This Row],[Key]],Table29[[#All],[Key]:[TSL Material Code3]],7,0) | P24: =VLOOKUP(Table27[[#This Row],[Key]],Table29[[#All],[Key]:[TSL Material Code3]],8,0) | Q24: 15 | R24: 15 | S24: 0 | T24: 22 | U24: =S24-R24 | W24: =U24+V24 | X24: =Q24-W24 | Y24: =IF(X24>0,X24,0)*150% | Z24: =ROUND(SUMIFS(meghsteelsales_previousmonth[Quantity],meghsteelsales_previousmonth[Length Bucket],Table27[[#This Row],[Bucket CTL]])/1000,0) | AA24: =ROUND(SUMIFS(meghsteelsales_currentmonth[Quantity],meghsteelsales_currentmonth[Length Bucket],Table27[[#This Row],[Bucket CTL]])/1000,0) | AB24: =Table27[[#This Row],[ INDENT FOR NOV-25 recommended]]+Table27[[#This Row],[order logg ]] | AC24: =Table27[[#This Row],[Before 20th]]+Table27[[#This Row],[ofter 20th]] | AD24: =IF(Table27[[#This Row],[Total Indent]]-Table27[[#This Row],[Total Supplied]]<0,0,Table27[[#This Row],[Total Indent]]-Table27[[#This Row],[Total Supplied]])
A25: TVS | B25: 943209 | C25: RUCHA | D25: ERW1 | E25: NON FIN | F25: ERW | G25: 25.4 | I25: 1.6 | J25: 6000 | K25: 6 | L25: =_xlfn.CONCAT(G25,I25,K25,F25,E25) | M25: =VLOOKUP(Table27[[#This Row],[Key]],Table29[[#All],[Key]:[TSL Material Code3]],4,0) | N25: =VLOOKUP(Table27[[#This Row],[Key]],Table29[[#All],[Key]:[TSL Material Code3]],5,0) | O25: =VLOOKUP(Table27[[#This Row],[Key]],Table29[[#All],[Key]:[TSL Material Code3]],7,0) | P25: =VLOOKUP(Table27[[#This Row],[Key]],Table29[[#All],[Key]:[TSL Material Code3]],8,0) | Q25: 30 | R25: 15 | S25: 10 | T25: 50 | U25: =S25-R25 | V25: 29 | W25: =U25+V25 | X25: =Q25-W25 | Y25: =IF(X25>0,X25,0)*150% | Z25: =ROUND(SUMIFS(meghsteelsales_previousmonth[Quantity],meghsteelsales_previousmonth[Length Bucket],Table27[[#This Row],[Bucket CTL]])/1000,0) | AA25: =ROUND(SUMIFS(meghsteelsales_currentmonth[Quantity],meghsteelsales_currentmonth[Length Bucket],Table27[[#This Row],[Bucket CTL]])/1000,0) | AB25: =Table27[[#This Row],[ INDENT FOR NOV-25 recommended]]+Table27[[#This Row],[order logg ]] | AC25: =Table27[[#This Row],[Before 20th]]+Table27[[#This Row],[ofter 20th]] | AD25: =IF(Table27[[#This Row],[Total Indent]]-Table27[[#This Row],[Total Supplied]]<0,0,Table27[[#This Row],[Total Indent]]-Table27[[#This Row],[Total Supplied]])
A26: RE | B26: 943211 | C26: BELRISE CHENNAI | D26: MICRO ALLOY | E26: NON FIN | F26: MICRO ALLOY | G26: 25.4 | I26: 1.6 | J26: 5840 | K26: 5.84 | L26: =_xlfn.CONCAT(G26,I26,K26,F26,E26) | M26: 25.4-0-1.6-ERW 2 MAHS-PE | N26: 25.4-0-1.6-ERW 2 MAHS-PE-5.84 | O26: 0789 | P26: 4149395 | Q26: 25 | R26: 10 | S26: 16.7 | T26: 0 | U26: =S26-R26 | V26: 21 | W26: =U26+V26 | X26: =Q26-W26 | Y26: =IF(X26>0,X26,0)*150% | Z26: =ROUND(SUMIFS(meghsteelsales_previousmonth[Quantity],meghsteelsales_previousmonth[Length Bucket],Table27[[#This Row],[Bucket CTL]])/1000,0) | AA26: =ROUND(SUMIFS(meghsteelsales_currentmonth[Quantity],meghsteelsales_currentmonth[Length Bucket],Table27[[#This Row],[Bucket CTL]])/1000,0) | AB26: =Table27[[#This Row],[ INDENT FOR NOV-25 recommended]]+Table27[[#This Row],[order logg ]] | AC26: =Table27[[#This Row],[Before 20th]]+Table27[[#This Row],[ofter 20th]] | AD26: =IF(Table27[[#This Row],[Total Indent]]-Table27[[#This Row],[Total Supplied]]<0,0,Table27[[#This Row],[Total Indent]]-Table27[[#This Row],[Total Supplied]])
A27: TVS | B27: 943209 | C27: RUCHA | D27: ERW1 | E27: NON FIN | F27: ERW | G27: 25.4 | I27: 2 | J27: 6050 | K27: 6.05 | L27: =_xlfn.CONCAT(G27,I27,K27,F27,E27) | M27: =VLOOKUP(Table27[[#This Row],[Key]],Table29[[#All],[Key]:[TSL Material Code3]],4,0) | N27: =VLOOKUP(Table27[[#This Row],[Key]],Table29[[#All],[Key]:[TSL Material Code3]],5,0) | O27: =VLOOKUP(Table27[[#This Row],[Key]],Table29[[#All],[Key]:[TSL Material Code3]],7,0) | P27: =VLOOKUP(Table27[[#This Row],[Key]],Table29[[#All],[Key]:[TSL Material Code3]],8,0) | Q27: 10 | R27: 0 | S27: 3 | T27: 0 | U27: =S27-R27 | W27: =U27+V27 | X27: =Q27-W27 | Y27: =IF(X27>0,X27,0)*150% | Z27: =ROUND(SUMIFS(meghsteelsales_previousmonth[Quantity],meghsteelsales_previousmonth[Length Bucket],Table27[[#This Row],[Bucket CTL]])/1000,0) | AA27: =ROUND(SUMIFS(meghsteelsales_currentmonth[Quantity],meghsteelsales_currentmonth[Length Bucket],Table27[[#This Row],[Bucket CTL]])/1000,0) | AB27: =Table27[[#This Row],[ INDENT FOR NOV-25 recommended]]+Table27[[#This Row],[order logg ]] | AC27: =Table27[[#This Row],[Before 20th]]+Table27[[#This Row],[ofter 20th]] | AD27: =IF(Table27[[#This Row],[Total Indent]]-Table27[[#This Row],[Total Supplied]]<0,0,Table27[[#This Row],[Total Indent]]-Table27[[#This Row],[Total Supplied]])
A28: TVS | B28: 943209 | C28: RUCHA | D28: ERW1 | E28: NON FIN | F28: ERW | G28: 25.4 | I28: 2.5 | J28: 5530 | K28: 5.53 | L28: =_xlfn.CONCAT(G28,I28,K28,F28,E28) | M28: =VLOOKUP(Table27[[#This Row],[Key]],Table29[[#All],[Key]:[TSL Material Code3]],4,0) | N28: =VLOOKUP(Table27[[#This Row],[Key]],Table29[[#All],[Key]:[TSL Material Code3]],5,0) | O28: =VLOOKUP(Table27[[#This Row],[Key]],Table29[[#All],[Key]:[TSL Material Code3]],7,0) | P28: =VLOOKUP(Table27[[#This Row],[Key]],Table29[[#All],[Key]:[TSL Material Code3]],8,0) | Q28: 40 | R28: 15 | S28: 5 | T28: 58 | U28: =S28-R28 | V28: 62 | W28: =U28+V28 | X28: =Q28-W28 | Y28: =IF(X28>0,X28,0)*150% | Z28: =ROUND(SUMIFS(meghsteelsales_previousmonth[Quantity],meghsteelsales_previousmonth[Length Bucket],Table27[[#This Row],[Bucket CTL]])/1000,0) | AA28: =ROUND(SUMIFS(meghsteelsales_currentmonth[Quantity],meghsteelsales_currentmonth[Length Bucket],Table27[[#This Row],[Bucket CTL]])/1000,0) | AB28: =Table27[[#This Row],[ INDENT FOR NOV-25 recommended]]+Table27[[#This Row],[order logg ]] | AC28: =Table27[[#This Row],[Before 20th]]+Table27[[#This Row],[ofter 20th]] | AD28: =IF(Table27[[#This Row],[Total Indent]]-Table27[[#This Row],[Total Supplied]]<0,0,Table27[[#This Row],[Total Indent]]-Table27[[#This Row],[Total Supplied]])
A29: TVS | B29: 943209 | C29: RUCHA,METALMAN | D29: ERW1 | E29: FIN CUT | F29: ERW | G29: 28.6 | I29: 1.2 | J29: 6000 | K29: 6 | L29: =_xlfn.CONCAT(G29,I29,K29,F29,E29) | M29: =VLOOKUP(Table27[[#This Row],[Key]],Table29[[#All],[Key]:[TSL Material Code3]],4,0) | N29: =VLOOKUP(Table27[[#This Row],[Key]],Table29[[#All],[Key]:[TSL Material Code3]],5,0) | O29: =VLOOKUP(Table27[[#This Row],[Key]],Table29[[#All],[Key]:[TSL Material Code3]],7,0) | P29: =VLOOKUP(Table27[[#This Row],[Key]],Table29[[#All],[Key]:[TSL Material Code3]],8,0) | Q29: 3 | R29: 0 | S29: 3.2 | T29: 0 | U29: =S29-R29 | W29: =U29+V29 | X29: =Q29-W29 | Y29: =IF(X29>0,X29,0)*150% | Z29: =ROUND(SUMIFS(meghsteelsales_previousmonth[Quantity],meghsteelsales_previousmonth[Length Bucket],Table27[[#This Row],[Bucket CTL]])/1000,0) | AA29: =ROUND(SUMIFS(meghsteelsales_currentmonth[Quantity],meghsteelsales_currentmonth[Length Bucket],Table27[[#This Row],[Bucket CTL]])/1000,0) | AB29: =Table27[[#This Row],[ INDENT FOR NOV-25 recommended]]+Table27[[#This Row],[order logg ]] | AC29: =Table27[[#This Row],[Before 20th]]+Table27[[#This Row],[ofter 20th]] | AD29: =IF(Table27[[#This Row],[Total Indent]]-Table27[[#This Row],[Total Supplied]]<0,0,Table27[[#This Row],[Total Indent]]-Table27[[#This Row],[Total Supplied]])
A30: TVS | B30: 943209 | C30: RUCHA | D30: CEW1 | E30: FIN CUT | F30: CEW | G30: 28.6 | I30: 2.65 | J30: 6000 | K30: 6 | L30: =_xlfn.CONCAT(G30,I30,K30,F30,E30) | M30: =VLOOKUP(Table27[[#This Row],[Key]],Table29[[#All],[Key]:[TSL Material Code3]],4,0) | N30: =VLOOKUP(Table27[[#This Row],[Key]],Table29[[#All],[Key]:[TSL Material Code3]],5,0) | O30: =VLOOKUP(Table27[[#This Row],[Key]],Table29[[#All],[Key]:[TSL Material Code3]],7,0) | P30: =VLOOKUP(Table27[[#This Row],[Key]],Table29[[#All],[Key]:[TSL Material Code3]],8,0) | Q30: 10 | R30: 0 | S30: 9 | T30: 0 | U30: =S30-R30 | W30: =U30+V30 | X30: =Q30-W30 | Y30: =IF(X30>0,X30,0)*150% | Z30: =ROUND(SUMIFS(meghsteelsales_previousmonth[Quantity],meghsteelsales_previousmonth[Length Bucket],Table27[[#This Row],[Bucket CTL]])/1000,0) | AA30: =ROUND(SUMIFS(meghsteelsales_currentmonth[Quantity],meghsteelsales_currentmonth[Length Bucket],Table27[[#This Row],[Bucket CTL]])/1000,0) | AB30: =Table27[[#This Row],[ INDENT FOR NOV-25 recommended]]+Table27[[#This Row],[order logg ]] | AC30: =Table27[[#This Row],[Before 20th]]+Table27[[#This Row],[ofter 20th]] | AD30: =IF(Table27[[#This Row],[Total Indent]]-Table27[[#This Row],[Total Supplied]]<0,0,Table27[[#This Row],[Total Indent]]-Table27[[#This Row],[Total Supplied]])
A31: TVS | B31: 943209 | C31: RUCHA,METALMAN | D31: ERW1 | E31: FIN CUT | F31: ERW | G31: 31.75 | I31: 1.2 | J31: 6000 | K31: 6 | L31: =_xlfn.CONCAT(G31,I31,K31,F31,E31) | M31: =VLOOKUP(Table27[[#This Row],[Key]],Table29[[#All],[Key]:[TSL Material Code3]],4,0) | N31: =VLOOKUP(Table27[[#This Row],[Key]],Table29[[#All],[Key]:[TSL Material Code3]],5,0) | O31: =VLOOKUP(Table27[[#This Row],[Key]],Table29[[#All],[Key]:[TSL Material Code3]],7,0) | P31: =VLOOKUP(Table27[[#This Row],[Key]],Table29[[#All],[Key]:[TSL Material Code3]],8,0) | Q31: 5 | R31: 0 | S31: 20 | T31: 8.8 | U31: =S31-R31 | V31: 1.7 | W31: =U31+V31 | X31: =Q31-W31 | Y31: =IF(X31>0,X31,0)*150% | Z31: =ROUND(SUMIFS(meghsteelsales_previousmonth[Quantity],meghsteelsales_previousmonth[Length Bucket],Table27[[#This Row],[Bucket CTL]])/1000,0) | AA31: =ROUND(SUMIFS(meghsteelsales_currentmonth[Quantity],meghsteelsales_currentmonth[Length Bucket],Table27[[#This Row],[Bucket CTL]])/1000,0) | AB31: =Table27[[#This Row],[ INDENT FOR NOV-25 recommended]]+Table27[[#This Row],[order logg ]] | AC31: =Table27[[#This Row],[Before 20th]]+Table27[[#This Row],[ofter 20th]] | AD31: =IF(Table27[[#This Row],[Total Indent]]-Table27[[#This Row],[Total Supplied]]<0,0,Table27[[#This Row],[Total Indent]]-Table27[[#This Row],[Total Supplied]])
A32: TVS | B32: 943209 | C32: RUCHA,METALMAN | D32: ERW1 | E32: FIN CUT | F32: ERW | G32: 31.75 | I32: 2 | J32: 6000 | K32: 6 | L32: =_xlfn.CONCAT(G32,I32,K32,F32,E32) | M32: =VLOOKUP(Table27[[#This Row],[Key]],Table29[[#All],[Key]:[TSL Material Code3]],4,0) | N32: =VLOOKUP(Table27[[#This Row],[Key]],Table29[[#All],[Key]:[TSL Material Code3]],5,0) | O32: =VLOOKUP(Table27[[#This Row],[Key]],Table29[[#All],[Key]:[TSL Material Code3]],7,0) | P32: =VLOOKUP(Table27[[#This Row],[Key]],Table29[[#All],[Key]:[TSL Material Code3]],8,0) | Q32: 10 | R32: 0 | S32: 10 | T32: 10 | U32: =S32-R32 | W32: =U32+V32 | X32: =Q32-W32 | Y32: =IF(X32>0,X32,0)*150% | Z32: =ROUND(SUMIFS(meghsteelsales_previousmonth[Quantity],meghsteelsales_previousmonth[Length Bucket],Table27[[#This Row],[Bucket CTL]])/1000,0) | AA32: =ROUND(SUMIFS(meghsteelsales_currentmonth[Quantity],meghsteelsales_currentmonth[Length Bucket],Table27[[#This Row],[Bucket CTL]])/1000,0) | AB32: =Table27[[#This Row],[ INDENT FOR NOV-25 recommended]]+Table27[[#This Row],[order logg ]] | AC32: =Table27[[#This Row],[Before 20th]]+Table27[[#This Row],[ofter 20th]] | AD32: =IF(Table27[[#This Row],[Total Indent]]-Table27[[#This Row],[Total Supplied]]<0,0,Table27[[#This Row],[Total Indent]]-Table27[[#This Row],[Total Supplied]])
A33: RE | B33: 943211 | C33: BELRISE | D33: ERW1 | E33: FIN CUT | F33: ERW | G33: 31.75 | I33: 2.3 | J33: 5920 | K33: 5.92 | L33: =_xlfn.CONCAT(G33,I33,K33,F33,E33) | M33: =VLOOKUP(Table27[[#This Row],[Key]],Table29[[#All],[Key]:[TSL Material Code3]],4,0) | N33: =VLOOKUP(Table27[[#This Row],[Key]],Table29[[#All],[Key]:[TSL Material Code3]],5,0) | O33: =VLOOKUP(Table27[[#This Row],[Key]],Table29[[#All],[Key]:[TSL Material Code3]],7,0) | P33: =VLOOKUP(Table27[[#This Row],[Key]],Table29[[#All],[Key]:[TSL Material Code3]],8,0) | Q33: 15 | R33: 5 | S33: 18 | T33: 0 | U33: =S33-R33 | W33: =U33+V33 | X33: =Q33-W33 | Y33: =IF(X33>0,X33,0)*150% | Z33: =ROUND(SUMIFS(meghsteelsales_previousmonth[Quantity],meghsteelsales_previousmonth[Length Bucket],Table27[[#This Row],[Bucket CTL]])/1000,0) | AA33: =ROUND(SUMIFS(meghsteelsales_currentmonth[Quantity],meghsteelsales_currentmonth[Length Bucket],Table27[[#This Row],[Bucket CTL]])/1000,0) | AB33: =Table27[[#This Row],[ INDENT FOR NOV-25 recommended]]+Table27[[#This Row],[order logg ]] | AC33: =Table27[[#This Row],[Before 20th]]+Table27[[#This Row],[ofter 20th]] | AD33: =IF(Table27[[#This Row],[Total Indent]]-Table27[[#This Row],[Total Supplied]]<0,0,Table27[[#This Row],[Total Indent]]-Table27[[#This Row],[Total Supplied]])
A34: TVS | B34: 943209 | C34: RUCHA,METALMAN | D34: ERW1 | E34: FIN CUT | F34: ERW | G34: 34.93 | I34: 1.2 | J34: 6000 | K34: 6 | L34: =_xlfn.CONCAT(G34,I34,K34,F34,E34) | M34: =VLOOKUP(Table27[[#This Row],[Key]],Table29[[#All],[Key]:[TSL Material Code3]],4,0) | N34: =VLOOKUP(Table27[[#This Row],[Key]],Table29[[#All],[Key]:[TSL Material Code3]],5,0) | O34: =VLOOKUP(Table27[[#This Row],[Key]],Table29[[#All],[Key]:[TSL Material Code3]],7,0) | P34: =VLOOKUP(Table27[[#This Row],[Key]],Table29[[#All],[Key]:[TSL Material Code3]],8,0) | Q34: 5 | R34: 1 | S34: 34 | T34: 0 | U34: =S34-R34 | V34: 62 | W34: =U34+V34 | X34: =Q34-W34 | Y34: =IF(X34>0,X34,0)*150% | Z34: =ROUND(SUMIFS(meghsteelsales_previousmonth[Quantity],meghsteelsales_previousmonth[Length Bucket],Table27[[#This Row],[Bucket CTL]])/1000,0) | AA34: =ROUND(SUMIFS(meghsteelsales_currentmonth[Quantity],meghsteelsales_currentmonth[Length Bucket],Table27[[#This Row],[Bucket CTL]])/1000,0) | AB34: =Table27[[#This Row],[ INDENT FOR NOV-25 recommended]]+Table27[[#This Row],[order logg ]] | AC34: =Table27[[#This Row],[Before 20th]]+Table27[[#This Row],[ofter 20th]] | AD34: =IF(Table27[[#This Row],[Total Indent]]-Table27[[#This Row],[Total Supplied]]<0,0,Table27[[#This Row],[Total Indent]]-Table27[[#This Row],[Total Supplied]])
A35: RE | B35: 943211 | C35: BELRISE | D35: ERW1 | E35: FIN CUT | F35: ERW | G35: 34.93 | I35: 1.2 | J35: 620 | K35: 0.62 | L35: =_xlfn.CONCAT(G35,I35,K35,F35,E35) | M35: =VLOOKUP(Table27[[#This Row],[Key]],Table29[[#All],[Key]:[TSL Material Code3]],4,0) | N35: =VLOOKUP(Table27[[#This Row],[Key]],Table29[[#All],[Key]:[TSL Material Code3]],5,0) | O35: =VLOOKUP(Table27[[#This Row],[Key]],Table29[[#All],[Key]:[TSL Material Code3]],7,0) | P35: =VLOOKUP(Table27[[#This Row],[Key]],Table29[[#All],[Key]:[TSL Material Code3]],8,0) | Q35: 10 | R35: 0 | S35: 0 | T35: 0 | U35: =S35-R35 | W35: =U35+V35 | X35: =Q35-W35 | Y35: =IF(X35>0,X35,0)*150% | Z35: =ROUND(SUMIFS(meghsteelsales_previousmonth[Quantity],meghsteelsales_previousmonth[Length Bucket],Table27[[#This Row],[Bucket CTL]])/1000,0) | AA35: =ROUND(SUMIFS(meghsteelsales_currentmonth[Quantity],meghsteelsales_currentmonth[Length Bucket],Table27[[#This Row],[Bucket CTL]])/1000,0) | AB35: =Table27[[#This Row],[ INDENT FOR NOV-25 recommended]]+Table27[[#This Row],[order logg ]] | AC35: =Table27[[#This Row],[Before 20th]]+Table27[[#This Row],[ofter 20th]] | AD35: =IF(Table27[[#This Row],[Total Indent]]-Table27[[#This Row],[Total Supplied]]<0,0,Table27[[#This Row],[Total Indent]]-Table27[[#This Row],[Total Supplied]])
A36: RE | B36: 943211 | C36: RAJSRIYA | D36: ERW1 | E36: FIN CUT | F36: ERW | G36: 34.93 | I36: 1.2 | J36: 650 | K36: 0.65 | L36: =_xlfn.CONCAT(G36,I36,K36,F36,E36) | M36: =VLOOKUP(Table27[[#This Row],[Key]],Table29[[#All],[Key]:[TSL Material Code3]],4,0) | N36: =VLOOKUP(Table27[[#This Row],[Key]],Table29[[#All],[Key]:[TSL Material Code3]],5,0) | O36: =VLOOKUP(Table27[[#This Row],[Key]],Table29[[#All],[Key]:[TSL Material Code3]],7,0) | P36: =VLOOKUP(Table27[[#This Row],[Key]],Table29[[#All],[Key]:[TSL Material Code3]],8,0) | Q36: 10 | R36: 0 | S36: 0 | T36: 0 | U36: =S36-R36 | W36: =U36+V36 | X36: =Q36-W36 | Y36: =IF(X36>0,X36,0)*150% | Z36: =ROUND(SUMIFS(meghsteelsales_previousmonth[Quantity],meghsteelsales_previousmonth[Length Bucket],Table27[[#This Row],[Bucket CTL]])/1000,0) | AA36: =ROUND(SUMIFS(meghsteelsales_currentmonth[Quantity],meghsteelsales_currentmonth[Length Bucket],Table27[[#This Row],[Bucket CTL]])/1000,0) | AB36: =Table27[[#This Row],[ INDENT FOR NOV-25 recommended]]+Table27[[#This Row],[order logg ]] | AC36: =Table27[[#This Row],[Before 20th]]+Table27[[#This Row],[ofter 20th]] | AD36: =IF(Table27[[#This Row],[Total Indent]]-Table27[[#This Row],[Total Supplied]]<0,0,Table27[[#This Row],[Total Indent]]-Table27[[#This Row],[Total Supplied]])
A37: HMSI | B37: 943210 | C37: BADVE | D37: ERW2 | E37: FIN CUT | F37: ERW | G37: 34 | I37: 1.4 | J37: 5660 | K37: 5.66 | L37: =_xlfn.CONCAT(G37,I37,K37,F37,E37) | M37: =VLOOKUP(Table27[[#This Row],[Key]],Table29[[#All],[Key]:[TSL Material Code3]],4,0) | N37: =VLOOKUP(Table27[[#This Row],[Key]],Table29[[#All],[Key]:[TSL Material Code3]],5,0) | O37: =VLOOKUP(Table27[[#This Row],[Key]],Table29[[#All],[Key]:[TSL Material Code3]],7,0) | P37: =VLOOKUP(Table27[[#This Row],[Key]],Table29[[#All],[Key]:[TSL Material Code3]],8,0) | Q37: 5 | R37: 0 | S37: 0 | T37: 0 | U37: =S37-R37 | W37: =U37+V37 | X37: =Q37-W37 | Y37: =IF(X37>0,X37,0)*150% | Z37: =ROUND(SUMIFS(meghsteelsales_previousmonth[Quantity],meghsteelsales_previousmonth[Length Bucket],Table27[[#This Row],[Bucket CTL]])/1000,0) | AA37: =ROUND(SUMIFS(meghsteelsales_currentmonth[Quantity],meghsteelsales_currentmonth[Length Bucket],Table27[[#This Row],[Bucket CTL]])/1000,0) | AB37: =Table27[[#This Row],[ INDENT FOR NOV-25 recommended]]+Table27[[#This Row],[order logg ]] | AC37: =Table27[[#This Row],[Before 20th]]+Table27[[#This Row],[ofter 20th]] | AD37: =IF(Table27[[#This Row],[Total Indent]]-Table27[[#This Row],[Total Supplied]]<0,0,Table27[[#This Row],[Total Indent]]-Table27[[#This Row],[Total Supplied]])
A38: TVS | B38: 943209 | C38: RUCHA,METALMAN | D38: ERW370 | E38: FIN CUT | F38: HST | G38: 38.1 | I38: 1.6 | J38: 6190 | K38: 6.19 | L38: =_xlfn.CONCAT(G38,I38,K38,F38,E38) | M38: =VLOOKUP(Table27[[#This Row],[Key]],Table29[[#All],[Key]:[TSL Material Code3]],4,0) | N38: =VLOOKUP(Table27[[#This Row],[Key]],Table29[[#All],[Key]:[TSL Material Code3]],5,0) | O38: =VLOOKUP(Table27[[#This Row],[Key]],Table29[[#All],[Key]:[TSL Material Code3]],7,0) | P38: =VLOOKUP(Table27[[#This Row],[Key]],Table29[[#All],[Key]:[TSL Material Code3]],8,0) | Q38: 40 | R38: 20 | S38: 23 | T38: 3.8 | U38: =S38-R38 | V38: 61 | W38: =U38+V38 | X38: =Q38-W38 | Y38: =IF(X38>0,X38,0)*150% | Z38: =ROUND(SUMIFS(meghsteelsales_previousmonth[Quantity],meghsteelsales_previousmonth[Length Bucket],Table27[[#This Row],[Bucket CTL]])/1000,0) | AA38: =ROUND(SUMIFS(meghsteelsales_currentmonth[Quantity],meghsteelsales_currentmonth[Length Bucket],Table27[[#This Row],[Bucket CTL]])/1000,0) | AB38: =Table27[[#This Row],[ INDENT FOR NOV-25 recommended]]+Table27[[#This Row],[order logg ]] | AC38: =Table27[[#This Row],[Before 20th]]+Table27[[#This Row],[ofter 20th]] | AD38: =IF(Table27[[#This Row],[Total Indent]]-Table27[[#This Row],[Total Supplied]]<0,0,Table27[[#This Row],[Total Indent]]-Table27[[#This Row],[Total Supplied]])
