Workbook

Sheet SOP
A1: Last refreshed: 7/31/2026, 5:36:08 AM
A3: For TSL
A4: 1 | B4: Update OMS for 056
A5: 2 | B5: Filter greater than 0 in qty to be logged
A6: 3 | B6: Log order min 5 MT
A7: 4 | B7: Update only peach color columns

Sheet vsm req
H1: VSM To Update | K1: 1721.5 | L1: 839 | M1: 210 | N1: 25 | O1: 99 | P1: 65 | Q1: 25 | R1: 25 | S1: 109 | T1: 126 | U1: 198.5
K2: Total schedule | L2: Rucha | M2: Metalman | N2: Marathwada | O2: Rajsriya tvs | P2: supangita | Q2: pams eng | R2: KP ENG | S2: Rajsriya RE | T2: belrise chennai | U2: Belrise malur
A3: S.NO | B3: Section | C3: Column1 | D3: O D | E3: Thk. | F3: Length | G3: Wt/Len | H3: key | I3: Grade | J3: FC/NFC
A4: 1 | C4: 943209 | D4: 12.7 | E4: 1.2 | F4: 6 | G4: 2.042 | H4: 12.7-0-1.2-ERW 1-PE | I4: ERW 1 | J4: NFC | K4: 6000 | L4: 6
A5: 2 | C5: 943210 | D5: 12.7 | E5: 1.4 | F5: 5.67 | G5: 2.212 | I5: ERW 1 | J5: NFC | K5: 1500 | U5: 1.5
A6: 3 | D6: 12.7 | E6: 1.4 | F6: 6 | G6: 2.341 | I6: ERW 1 | J6: NFC | K6: 0
A7: 4 | D7: 12.7 | E7: 1.4 | F7: 6.035 | G7: 2.355 | I7: ERW 1 | J7: NFC | K7: 0
A8: 5 | C8: 943210 | D8: 12.7 | E8: 1.6 | F8: 6 | G8: 2.628 | H8: 12.7-0-1.6-ERW 1-PE | I8: ERW 1 | J8: NFC | K8: 0
A9: 6 | D9: 12.7 | E9: 2 | F9: 6 | G9: 3.167 | I9: ERW 1 | J9: NFC | K9: 2000 | L9: 2
A10: 7 | D10: 14 | E10: 2.45 | F10: 5 | K10: 0
A11: 8 | D11: 15.88 | E11: 1 | F11: 6.19 | G11: 2.272 | H11: 15.88-0-1-ERW 1-PE | I11: ERW 1 | J11: NFC | K11: 0
A12: 9 | C12: 943210 | D12: 15.88 | E12: 1.2 | F12: 6 | G12: 2.607 | H12: 15.88-0-1.2-ERW 1-PE | I12: ERW 1 | J12: NFC | K12: 5000 | L12: 5
A13: 10 | D13: 15.88 | E13: 1.4 | F13: 6 | G13: 2.607 | I13: ERW 1 | J13: NFC | K13: 0
A14: 11 | D14: 15.88 | E14: 1.6 | F14: 6 | G14: 3.381 | H14: 15.88-0-1.6-ERW 1-PE | I14: ERW 1 | J14: NFC | K14: 1000 | L14: 1
A15: 12 | C15: 943209 | D15: 15.88 | E15: 2 | F15: 6 | G15: 4.108 | H15: 15.88-0-2-ERW 1-PE | I15: ERW 1 | J15: NFC | K15: 3000 | U15: 3
A16: 13 | D16: 16.8 | E16: 2.4 | F16: 4.4 | G16: 3.75 | H16: 16.1-10.4-2.7-CEW-CEW | I16: ERW 1 | J16: NFC | K16: 0
A17: 14 | D17: 18.2 | E17: 1 | F17: 6.145 | G17: 2.607 | H17: 18.2-0-1-ERW 1-PE | I17: ERW 1 | J17: NFC | K17: 5000 | L17: 5
A18: 15 | C18: 943210 | D18: 19.05 | E18: 1.4 | F18: 6 | G18: 3.656 | I18: ERW 2 | J18: NFC | K18: 11000 | U18: 11
A19: 16 | C19: 943209 | D19: 19.05 | E19: 1.6 | F19: 6 | G19: 4.062 | H19: 19.05-0-1.6-ERW 1-PE | I19: ERW 1 | J19: NFC | K19: 25000 | T19: 15 | U19: 10
A20: 17 | D20: 19.05 | E20: 1.6 | F20: 6.2 | G20: 4.131 | H20: 19.05-0-1.6-ERW 1-PE | I20: ERW 1 | J20: NFC | K20: 0
A21: 18 | C21: 943209 | D21: 19.05 | E21: 2 | F21: 5.8 | G21: 4.878 | H21: 19.05-0-2-ERW 1-PE | I21: ERW 1 | J21: NFC | K21: 17000 | O21: 17
A22: 19 | D22: 19.05 | E22: 2 | F22: 5.841 | G22: 4.912 | H22: 19.05-0-2-ERW 1-PE | I22: ERW 1 | J22: NFC | K22: 48000 | L22: 45 | M22: 3
A23: 20 | D23: 19.05 | E23: 2.3 | F23: 6 | G23: 6.651 | H23: 19.05-0-2.3-ERW 1-PE | I23: ERW 1 | J23: NFC | K23: 4000 | M23: 4
A24: 21 | D24: 19.05 | E24: 2.3 | F24: 6.32 | G24: 6.651 | H24: 19.05-0-2.3-ERW 1-PE | I24: ERW 1 | J24: NFC | K24: 0
A25: 22 | D25: 19.05 | E25: 2.3 | F25: 7 | K25: 30000 | L25: 30
A26: 23 | D26: 19 | E26: 3.25 | F26: 6.2 | K26: 0
A27: 24 | C27: 943209 | D27: 21.4 | E27: 1.6 | F27: 6 | G27: 4.688 | H27: 21.4-0-1.6-ERW 1-PE | I27: ERW 1 | J27: NFC | K27: 5000 | L27: 5
A28: 25 | C28: 943209 | D28: 21.4 | E28: 2 | F28: 5.66 | I28: ERW 1 | J28: NFC | K28: 0
A29: 26 | D29: 22.2 | E29: 1.2 | F29: 5.3 | K29: 9500 | L29: 8 | M29: 1.5
A30: 27 | C30: 943209 | D30: 22.2 | E30: 1.2 | F30: 5.87 | G30: 3.648 | H30: 22.23-0-1.2-ERW 1-PE | I30: ERW 1 | J30: NFC | K30: 10000 | L30: 10
A31: 28 | C31: 943209 | D31: 22.2 | E31: 1.4 | F31: 6 | G31: 4.309 | I31: ERW 2 | J31: NFC | K31: 6000 | U31: 6
A32: 29 | C32: 943209 | D32: 22.2 | E32: 1.6 | F32: 5.27 | G32: 4.609 | H32: 22.23-0-1.6-ERW 1-PE | I32: ERW 1 | J32: NFC | K32: 1000 | M32: 1
A33: 30 | C33: 943209 | D33: 22.2 | E33: 1.6 | F33: 5.264 | G33: 4.284 | H33: 22.23-0-1.6-ERW 1-PE | I33: ERW 1 | J33: NFC | K33: 55000 | L33: 30 | N33: 25
A34: 31 | C34: 943209 | D34: 22.2 | E34: 1.6 | F34: 5.685 | G34: 4.877 | H34: 22.23-0-1.6-ERW 1-PE | I34: ERW 1 | J34: NFC | K34: 0
A35: 32 | C35: 943209 | D35: 22.2 | E35: 1.6 | F35: 5.8 | G35: 4.609 | H35: 22.23-0-1.6-ERW 1-PE | I35: ERW 1 | J35: NFC | K35: 0
A36: 33 | C36: 943209 | D36: 22.2 | E36: 1.6 | F36: 5.67 | G36: 4.877 | H36: 22.23-0-1.6-ERW 1-PE | I36: ERW 1 | J36: NFC | K36: 50000 | L36: 50
A37: 34 | C37: 943209 | D37: 22.2 | E37: 2 | F37: 5.1 | G37: 5.081 | H37: 22.23-0-2-ERW 1-PE | I37: ERW 1 | J37: NFC | K37: 0
A38: 35 | C38: 943209 | D38: 22.2 | E38: 2 | F38: 5.4 | G38: 5.38 | H38: 22.23-0-2-ERW 1-FC | I38: ERW 1 | J38: FC | K38: 0
A39: 36 | D39: 22.2 | E39: 2 | F39: 5.5 | K39: 0
A40: 37 | D40: 22.2 | E40: 2 | F40: 5.65 | I40: ERW 1 | J40: NFC | K40: 0
...

Sheet TVSM
H1: VSM To Update | K1: 30.07.26
J2: =SUM(J3:J96) -> 1263 | K2: =SUM(K3:K96) -> 990.836 | L2: =SUM(L3:L96) -> 1167.62 | M2: =SUM(M3:M96) -> 839 | N2: =SUM(N3:N96) -> 210 | O2: =SUM(O3:O96) -> 25 | P2: =SUM(P3:P96) -> 99 | Q2: =SUM(Q3:Q96) -> 65 | ... T2: =SUM(T3:T96) -> 0
A3: S.NO | B3: Section | C3: Column1 | D3: O D | E3: Thk. | F3: Wt/Len | G3: key | H3: Grade | I3: FC/NFC | J3: VSM Requirement | K3: VSM Sales | L3: VSM Stock | M3: Rucha | N3: Metalman | O3: Marathwada | P3: Rajsriya tvs | Q3: supangita | R3: pams eng | T3: 2
A4: 1 | C4: 943209 | D4: 12.7 | E4: 1.2 | F4: 2.042 | G4: 12.7-0-1.2-ERW 1-PE | H4: ERW 1 | I4: NFC | J4: =SUM(M4:R4) -> 6 | K4: =(759+180+613+316+346+511+629+180+173+338+390)/1000 -> 4.435 | L4: =ROUND(SUMIFS(Table3[Stock],Table3[key],Table1[[#This Row],[key]])/1000+SUMIFS(Table3[In Transit],Table3[key],Table1[[#This Row],[key]])/1000,2) -> 10.28 | M4: 6
A5: 2 | C5: 943210 | D5: 12.7 | E5: 1.4 | F5: 2.212 | H5: ERW 1 | I5: NFC | J5: =SUM(M5:R5) -> 0 | L5: =ROUND(SUMIFS(Table3[Stock],Table3[key],Table1[[#This Row],[key]])/1000+SUMIFS(Table3[In Transit],Table3[key],Table1[[#This Row],[key]])/1000,2) -> 0
A6: 3 | D6: 12.7 | E6: 1.4 | F6: 2.341 | H6: ERW 1 | I6: NFC | J6: =SUM(M6:R6) -> 0 | L6: =ROUND(SUMIFS(Table3[Stock],Table3[key],Table1[[#This Row],[key]])/1000+SUMIFS(Table3[In Transit],Table3[key],Table1[[#This Row],[key]])/1000,2) -> 0
A7: 4 | D7: 12.7 | E7: 1.4 | F7: 2.355 | H7: ERW 1 | I7: NFC | J7: =SUM(M7:R7) -> 0 | L7: =ROUND(SUMIFS(Table3[Stock],Table3[key],Table1[[#This Row],[key]])/1000+SUMIFS(Table3[In Transit],Table3[key],Table1[[#This Row],[key]])/1000,2) -> 0
A8: 5 | C8: 943210 | D8: 12.7 | E8: 1.6 | F8: 2.628 | G8: 12.7-0-1.6-ERW 1-PE | H8: ERW 1 | I8: NFC | J8: =SUM(M8:R8) -> 0 | L8: =ROUND(SUMIFS(Table3[Stock],Table3[key],Table1[[#This Row],[key]])/1000+SUMIFS(Table3[In Transit],Table3[key],Table1[[#This Row],[key]])/1000,2) -> 2.74
A9: 6 | D9: 12.7 | E9: 2 | F9: 3.167 | H9: ERW 1 | I9: NFC | J9: =SUM(M9:R9) -> 2 | L9: =ROUND(SUMIFS(Table3[Stock],Table3[key],Table1[[#This Row],[key]])/1000+SUMIFS(Table3[In Transit],Table3[key],Table1[[#This Row],[key]])/1000,2) -> 0 | M9: 2
A10: 7 | D10: 14 | E10: 2.45 | J10: =SUM(M10:R10) -> 0 | L10: =ROUND(SUMIFS(Table3[Stock],Table3[key],Table1[[#This Row],[key]])/1000+SUMIFS(Table3[In Transit],Table3[key],Table1[[#This Row],[key]])/1000,2) -> 0
A11: 8 | D11: 15.88 | E11: 1 | F11: 2.272 | G11: 15.88-0-1-ERW 1-PE | H11: ERW 1 | I11: NFC | J11: =SUM(M11:R11) -> 0 | L11: =ROUND(SUMIFS(Table3[Stock],Table3[key],Table1[[#This Row],[key]])/1000+SUMIFS(Table3[In Transit],Table3[key],Table1[[#This Row],[key]])/1000,2) -> 0
A12: 9 | C12: 943210 | D12: 15.88 | E12: 1.2 | F12: 2.607 | G12: 15.88-0-1.2-ERW 1-PE | H12: ERW 1 | I12: NFC | J12: =SUM(M12:R12) -> 5 | K12: =(1222+1309)/1000 -> 2.531 | L12: =ROUND(SUMIFS(Table3[Stock],Table3[key],Table1[[#This Row],[key]])/1000+SUMIFS(Table3[In Transit],Table3[key],Table1[[#This Row],[key]])/1000,2) -> 1.57 | M12: 5
A13: 10 | D13: 15.88 | E13: 1.4 | F13: 2.607 | H13: ERW 1 | I13: NFC | J13: =SUM(M13:R13) -> 0 | L13: =ROUND(SUMIFS(Table3[Stock],Table3[key],Table1[[#This Row],[key]])/1000+SUMIFS(Table3[In Transit],Table3[key],Table1[[#This Row],[key]])/1000,2) -> 0
A14: 11 | D14: 15.88 | E14: 1.6 | F14: 3.381 | G14: 15.88-0-1.6-ERW 1-PE | H14: ERW 1 | I14: NFC | J14: =SUM(M14:R14) -> 1 | K14: =(481)/1000 -> 0.481 | L14: =ROUND(SUMIFS(Table3[Stock],Table3[key],Table1[[#This Row],[key]])/1000+SUMIFS(Table3[In Transit],Table3[key],Table1[[#This Row],[key]])/1000,2) -> 10.66 | M14: 1
A15: 12 | C15: 943209 | D15: 15.88 | E15: 2 | F15: 4.108 | G15: 15.88-0-2-ERW 1-PE | H15: ERW 1 | I15: NFC | J15: =SUM(M15:R15) -> 0 | K15: =(6075)/1000 -> 6.075 | L15: =ROUND(SUMIFS(Table3[Stock],Table3[key],Table1[[#This Row],[key]])/1000+SUMIFS(Table3[In Transit],Table3[key],Table1[[#This Row],[key]])/1000,2) -> 0
A16: 13 | D16: 16.8 | E16: 2.4 | F16: 3.75 | G16: 16.1-10.4-2.7-CEW-CEW | H16: ERW 1 | I16: NFC | J16: =SUM(M16:R16) -> 0 | L16: =ROUND(SUMIFS(Table3[Stock],Table3[key],Table1[[#This Row],[key]])/1000+SUMIFS(Table3[In Transit],Table3[key],Table1[[#This Row],[key]])/1000,2) -> 0
A17: 14 | D17: 18.2 | E17: 1 | F17: 2.607 | G17: 18.2-0-1-ERW 1-PE | H17: ERW 1 | I17: NFC | J17: =SUM(M17:R17) -> 5 | K17: =(593+424+424+127+212)/1000 -> 1.78 | L17: =ROUND(SUMIFS(Table3[Stock],Table3[key],Table1[[#This Row],[key]])/1000+SUMIFS(Table3[In Transit],Table3[key],Table1[[#This Row],[key]])/1000,2) -> 6.26 | M17: 5
A18: 15 | C18: 943210 | D18: 19.05 | E18: 1.4 | F18: 3.656 | H18: ERW 2 | I18: NFC | J18: =SUM(M18:R18) -> 0 | L18: =ROUND(SUMIFS(Table3[Stock],Table3[key],Table1[[#This Row],[key]])/1000+SUMIFS(Table3[In Transit],Table3[key],Table1[[#This Row],[key]])/1000,2) -> 0
A19: 18 | C19: 943209 | D19: 19.05 | E19: 2 | F19: 4.878 | G19: 19.05-0-2-ERW 1-PE | H19: ERW 1 | I19: NFC | J19: 65 | K19: =(4899+1103+3634+1379+1379+3322+5930+5554+2114+689+1379+1241)/1000 -> 32.623 | L19: =ROUND(SUMIFS(Table3[Stock],Table3[key],Table1[[#This Row],[key]])/1000+SUMIFS(Table3[In Transit],Table3[key],Table1[[#This Row],[key]])/1000,2) -> 4.71 | M19: 45 | N19: 3 | P19: 17
A20: 20 | D20: 19.05 | E20: 2.3 | F20: 6.651 | G20: 19.05-0-2.3-ERW 1-PE | H20: ERW 1 | I20: NFC | J20: 34 | K20: =(475+2345+2688+2071+3776+7089+3109+1216+3002)/1000 -> 25.771 | L20: =ROUND(SUMIFS(Table3[Stock],Table3[key],Table1[[#This Row],[key]])/1000+SUMIFS(Table3[In Transit],Table3[key],Table1[[#This Row],[key]])/1000,2) -> 17.23 | M20: 30 | N20: 4
A21: 24 | C21: 943209 | D21: 21.4 | E21: 1.6 | F21: 4.688 | G21: 21.4-0-1.6-ERW 1-PE | H21: ERW 1 | I21: NFC | J21: =SUM(M21:R21) -> 5 | K21: =(73)/1000 -> 0.073 | L21: =ROUND(SUMIFS(Table3[Stock],Table3[key],Table1[[#This Row],[key]])/1000+SUMIFS(Table3[In Transit],Table3[key],Table1[[#This Row],[key]])/1000,2) -> 0 | M21: 5
A22: 25 | C22: 943209 | D22: 21.4 | E22: 2 | H22: ERW 1 | I22: NFC | J22: =SUM(M22:R22) -> 0 | L22: =ROUND(SUMIFS(Table3[Stock],Table3[key],Table1[[#This Row],[key]])/1000+SUMIFS(Table3[In Transit],Table3[key],Table1[[#This Row],[key]])/1000,2) -> 0
A23: 26 | D23: 22.2 | E23: 1.2 | F23: 3.648 | G23: 22.23-0-1.2-ERW 1-PE | H23: ERW 1 | I23: NFC | J23: 19.5 | K23: =(2156+1175+964+967+498+227+1061+1198+1625+389+893+693)/1000 -> 11.846 | L23: =ROUND(SUMIFS(Table3[Stock],Table3[key],Table1[[#This Row],[key]])/1000+SUMIFS(Table3[In Transit],Table3[key],Table1[[#This Row],[key]])/1000,2) -> 21.04 | M23: 18 | N23: 1.5
A24: 28 | C24: 943209 | D24: 22.2 | E24: 1.4 | F24: 4.309 | H24: ERW 2 | I24: NFC | J24: =SUM(M24:R24) -> 0 | L24: =ROUND(SUMIFS(Table3[Stock],Table3[key],Table1[[#This Row],[key]])/1000+SUMIFS(Table3[In Transit],Table3[key],Table1[[#This Row],[key]])/1000,2) -> 0
A25: 29 | C25: 943209 | D25: 22.2 | E25: 1.6 | F25: 4.609 | G25: 22.23-0-1.6-ERW 1-PE | H25: ERW 1 | I25: NFC | J25: 106 | K25: =(10477+9811+3436+3431+7478+1854+10424+7865+2597+5930+8857+3226)/1000 -> 75.386 | L25: =ROUND(SUMIFS(Table3[Stock],Table3[key],Table1[[#This Row],[key]])/1000+SUMIFS(Table3[In Transit],Table3[key],Table1[[#This Row],[key]])/1000,2) -> 139.45 | M25: 80 | N25: 1 | O25: 25
A26: 35 | C26: 943209 | D26: 22.2 | E26: 2 | F26: 5.38 | G26: 22.23-0-2-ERW 1-FC | H26: ERW 1 | I26: FC | J26: =SUM(M26:R26) -> 0 | L26: =ROUND(SUMIFS(Table3[Stock],Table3[key],Table1[[#This Row],[key]])/1000+SUMIFS(Table3[In Transit],Table3[key],Table1[[#This Row],[key]])/1000,2) -> 34.19
A27: 36 | D27: 22.2 | E27: 2 | J27: =SUM(M27:R27) -> 0 | L27: =ROUND(SUMIFS(Table3[Stock],Table3[key],Table1[[#This Row],[key]])/1000+SUMIFS(Table3[In Transit],Table3[key],Table1[[#This Row],[key]])/1000,2) -> 0
A28: 37 | D28: 22.2 | E28: 2 | H28: ERW 1 | I28: NFC | J28: =SUM(M28:R28) -> 0 | L28: =ROUND(SUMIFS(Table3[Stock],Table3[key],Table1[[#This Row],[key]])/1000+SUMIFS(Table3[In Transit],Table3[key],Table1[[#This Row],[key]])/1000,2) -> 0
A29: 38 | C29: 943209 | D29: 22.2 | E29: 2 | F29: 5.928 | G29: 22.23-0-2-ERW 1-PE | H29: ERW 1 | I29: NFC | J29: =SUM(M29:R29) -> 150 | K29: =(18615+15009+13801+6900+3404+12621+18743+15333+8034+18649+8128+12297)/1000 -> 151.534 | L29: =ROUND(SUMIFS(Table3[Stock],Table3[key],Table1[[#This Row],[key]])/1000+SUMIFS(Table3[In Transit],Table3[key],Table1[[#This Row],[key]])/1000,2) -> 82.92 | M29: 90 | Q29: 60
A30: 39 | C30: 943209 | D30: 22.2 | E30: 2 | F30: 5.978 | G30: 22.23-0-2-ERW 2-FC | H30: ERW 2 | I30: FC | J30: =SUM(M30:R30) -> 60 | L30: =ROUND(SUMIFS(Table3[Stock],Table3[key],Table1[[#This Row],[key]])/1000+SUMIFS(Table3[In Transit],Table3[key],Table1[[#This Row],[key]])/1000,2) -> 35.25 | M30: 60
A31: 40 | D31: 22.2 | E31: 2.3 | F31: 6.502 | G31: 22.23-0-2.3-ERW 1-PE | H31: ERW 2 | I31: NFC | J31: =SUM(M31:R31) -> 0 | L31: =ROUND(SUMIFS(Table3[Stock],Table3[key],Table1[[#This Row],[key]])/1000+SUMIFS(Table3[In Transit],Table3[key],Table1[[#This Row],[key]])/1000,2) -> 0
A32: 42 | C32: 943210 | D32: 25.4 | E32: 1.4 | F32: 4.583 | H32: ERW 2 | I32: FC | J32: =SUM(M32:R32) -> 0 | L32: =ROUND(SUMIFS(Table3[Stock],Table3[key],Table1[[#This Row],[key]])/1000+SUMIFS(Table3[In Transit],Table3[key],Table1[[#This Row],[key]])/1000,2) -> 0
A33: 43 | C33: 943210 | D33: 25.4 | E33: 1.4 | H33: ERW 1 | I33: FC | J33: =SUM(M33:R33) -> 0 | L33: =ROUND(SUMIFS(Table3[Stock],Table3[key],Table1[[#This Row],[key]])/1000+SUMIFS(Table3[In Transit],Table3[key],Table1[[#This Row],[key]])/1000,2) -> 0
A34: 44 | D34: 25.4 | E34: 1.6 | G34: 25.4-0-1.6-ERW 1-FC | H34: ERW 1 | I34: NFC | J34: 41 | K34: =(4840+2558+4825+976+4135+3161+10401)/1000 -> 30.896 | L34: =ROUND(SUMIFS(Table3[Stock],Table3[key],Table1[[#This Row],[key]])/1000+SUMIFS(Table3[In Transit],Table3[key],Table1[[#This Row],[key]])/1000,2) -> 41.07 | M34: 41
A35: 45 | D35: 25.4 | E35: 1.6 | J35: =SUM(M35:R35) -> 0 | L35: =ROUND(SUMIFS(Table3[Stock],Table3[key],Table1[[#This Row],[key]])/1000+SUMIFS(Table3[In Transit],Table3[key],Table1[[#This Row],[key]])/1000,2) -> 0
A36: 47 | C36: 943209 | D36: 25.4 | E36: 2 | F36: 6.74 | G36: 25.4-0-2-ERW 1-FC | H36: ERW 1 | I36: NFC | J36: =SUM(M36:R36) -> 10 | K36: =(7540+1845+898+3266+4130+1633)/1000 -> 19.312 | L36: =ROUND(SUMIFS(Table3[Stock],Table3[key],Table1[[#This Row],[key]])/1000+SUMIFS(Table3[In Transit],Table3[key],Table1[[#This Row],[key]])/1000,2) -> 27.5 | M36: 10
A37: 48 | C37: 943209 | D37: 25.4 | E37: 2 | H37: ERW 1 | I37: NFC | J37: =SUM(M37:R37) -> 0 | L37: =ROUND(SUMIFS(Table3[Stock],Table3[key],Table1[[#This Row],[key]])/1000+SUMIFS(Table3[In Transit],Table3[key],Table1[[#This Row],[key]])/1000,2) -> 0
A38: 50 | C38: 943209 | D38: 25.4 | E38: 2.5 | F38: 7.808 | G38: 25.4-0-2.5-ERW 1-FC | H38: ERW 1 | I38: FC | J38: =SUM(M38:R38) -> 56 | L38: =ROUND(SUMIFS(Table3[Stock],Table3[key],Table1[[#This Row],[key]])/1000+SUMIFS(Table3[In Transit],Table3[key],Table1[[#This Row],[key]])/1000,2) -> 44.17 | M38: 56
A39: 51 | D39: 25.4 | E39: 2.5 | F39: 8.33 | G39: 25.4-0-2.5-ERW 1-FC | H39: ERW 1 | I39: FC | J39: =SUM(M39:R39) -> 0 | K39: =(16582+6632+13625+13265+10200+5527)/1000 -> 65.831 | L39: =ROUND(SUMIFS(Table3[Stock],Table3[key],Table1[[#This Row],[key]])/1000+SUMIFS(Table3[In Transit],Table3[key],Table1[[#This Row],[key]])/1000,2) -> 0
A40: 52 | D40: 25.4 | E40: 2.6 | F40: 5.117 | G40: 25.4-0-2.5-CEW-CEW | H40: CEW | I40: FC | J40: =SUM(M40:R40) -> 0 | L40: =ROUND(SUMIFS(Table3[Stock],Table3[key],Table1[[#This Row],[key]])/1000+SUMIFS(Table3[In Transit],Table3[key],Table1[[#This Row],[key]])/1000,2) -> 3.48
...

Sheet vsm stock
H1: VSM To Update | L1: TSL to update
P2: =SUM(Table3[Schedule]) -> 1783501 | Q2: =SUM(Table3[Stock]) -> 1239154.4 | R2: =SUM(Table3[In Transit]) -> 277507
A3: S.NO | B3: Section | C3: Column1 | D3: O D | E3: Thk. | F3: Length | G3: Wt/Len | H3: key | I3: Grade | J3: FC/NFC | K3: HR/CR | L3: NOS | M3: 056 | N3: 0789 | O3: 0788 | P3: Schedule | Q3: Stock | R3: In Transit | S3: Column2 | T3: Coverage | U3: 056 Order | V3: 0789 Order | W3: 0788 Order | X3: 789 Order | Y3: Order qty to be logged | Z3: Coverage post order | AA3: Remark
A4: 1 | C4: 943209 | D4: 12.7 | E4: 1.2 | F4: 6 | G4: 2.042 | H4: 12.7-0-1.2-ERW 1-PE | I4: ERW 1 | J4: NFC | L4: 5032 | N4: 1939985 | P4: ='vsm req'!K4 -> 6000 | Q4: =((D4-E4)*E4*0.0246615*F4*L4) -> 10275.204 | R4: 0 | T4: =ROUND((Q4+Table3[[#This Row],[In Transit]])/P4*30,0) -> 51 | U4: 0 | Y4: =IF((45-Table3[[#This Row],[Coverage post order]])>0,Table3[[#This Row],[Schedule]]*1.5,0) -> 0 | Z4: =ROUND((Table3[[#This Row],[Stock]]+Table3[[#This Row],[056 Order]]+Table3[[#This Row],[0789 Order]]+Table3[[#This Row],[0788 Order]]+Table3[[#This Row],[In Transit]])/Table3[[#This Row],[Schedule]]*30,0) -> 51 | AA4: 789
A5: 2 | C5: 943210 | D5: 12.7 | E5: 1.4 | F5: 5.67 | G5: 2.212 | I5: ERW 1 | J5: NFC | L5: 393 | N5: 3552188 | P5: ='vsm req'!K5 -> 1500 | Q5: =((D5-E5)*E5*0.0246615*F5*L5) -> 869.36385 | T5: =ROUND((Q5+Table3[[#This Row],[In Transit]])/P5*30,0) -> 17 | V5: 2250 | Y5: =IF((45-Table3[[#This Row],[Coverage post order]])>0,Table3[[#This Row],[Schedule]]*1.5,0) -> 0 | Z5: =ROUND((Table3[[#This Row],[Stock]]+Table3[[#This Row],[056 Order]]+Table3[[#This Row],[0789 Order]]+Table3[[#This Row],[0788 Order]]+Table3[[#This Row],[In Transit]])/Table3[[#This Row],[Schedule]]*30,0) -> 62 | AA5: 0789
A6: 3 | D6: 12.7 | E6: 1.4 | F6: 6 | G6: 2.341 | I6: ERW 1 | J6: NFC | L6: 0 | N6: 1931117 | P6: ='vsm req'!K6 -> 0 | Q6: =((D6-E6)*E6*0.0246615*F6*L6) -> 0 | T6: =ROUND((Q6+Table3[[#This Row],[In Transit]])/P6*30,0) -> #DIV/0! | Y6: =IF((45-Table3[[#This Row],[Coverage post order]])>0,Table3[[#This Row],[Schedule]]*1.5,0) -> #DIV/0! | Z6: =ROUND((Table3[[#This Row],[Stock]]+Table3[[#This Row],[056 Order]]+Table3[[#This Row],[0789 Order]]+Table3[[#This Row],[0788 Order]]+Table3[[#This Row],[In Transit]])/Table3[[#This Row],[Schedule]]*30,0) -> #DIV/0!
A7: 4 | D7: 12.7 | E7: 1.4 | F7: 6.035 | G7: 2.355 | I7: ERW 1 | J7: NFC | L7: 0 | P7: ='vsm req'!K7 -> 0 | Q7: =((D7-E7)*E7*0.0246615*F7*L7) -> 0 | T7: =ROUND((Q7+Table3[[#This Row],[In Transit]])/P7*30,0) -> #DIV/0! | Y7: =IF((45-Table3[[#This Row],[Coverage post order]])>0,Table3[[#This Row],[Schedule]]*1.5,0) -> #DIV/0! | Z7: =ROUND((Table3[[#This Row],[Stock]]+Table3[[#This Row],[056 Order]]+Table3[[#This Row],[0789 Order]]+Table3[[#This Row],[0788 Order]]+Table3[[#This Row],[In Transit]])/Table3[[#This Row],[Schedule]]*30,0) -> #DIV/0!
A8: 5 | C8: 943210 | D8: 12.7 | E8: 1.6 | F8: 6 | G8: 2.628 | H8: 12.7-0-1.6-ERW 1-PE | I8: ERW 1 | J8: NFC | L8: 1043 | N8: 1931154 | P8: ='vsm req'!K8 -> 0 | Q8: =((D8-E8)*E8*0.0246615*F8*L8) -> 2740.9304 | T8: =ROUND((Q8+Table3[[#This Row],[In Transit]])/P8*30,0) -> #DIV/0! | Y8: =IF((45-Table3[[#This Row],[Coverage post order]])>0,Table3[[#This Row],[Schedule]]*1.5,0) -> #DIV/0! | Z8: =ROUND((Table3[[#This Row],[Stock]]+Table3[[#This Row],[056 Order]]+Table3[[#This Row],[0789 Order]]+Table3[[#This Row],[0788 Order]]+Table3[[#This Row],[In Transit]])/Table3[[#This Row],[Schedule]]*30,0) -> #DIV/0!
A9: 6 | D9: 12.7 | E9: 2 | F9: 6 | G9: 3.167 | I9: ERW 1 | J9: NFC | L9: 0 | P9: ='vsm req'!K9 -> 2000 | Q9: =((D9-E9)*E9*0.0246615*F9*L9) -> 0 | T9: =ROUND((Q9+Table3[[#This Row],[In Transit]])/P9*30,0) -> 0 | Y9: =IF((45-Table3[[#This Row],[Coverage post order]])>0,Table3[[#This Row],[Schedule]]*1.5,0) -> 3000 | Z9: =ROUND((Table3[[#This Row],[Stock]]+Table3[[#This Row],[056 Order]]+Table3[[#This Row],[0789 Order]]+Table3[[#This Row],[0788 Order]]+Table3[[#This Row],[In Transit]])/Table3[[#This Row],[Schedule]]*30,0) -> 0 | AA9: Check
D10: 14 | E10: 2.45 | F10: 5 | L10: 0 | P10: ='vsm req'!K10 -> 0 | Q10: =((D10-E10)*E10*0.0246615*F10*L10) -> 0 | T10: =ROUND((Q10+Table3[[#This Row],[In Transit]])/P10*30,0) -> #DIV/0! | Y10: =IF((45-Table3[[#This Row],[Coverage post order]])>0,Table3[[#This Row],[Schedule]]*1.5,0) -> #DIV/0! | Z10: =ROUND((Table3[[#This Row],[Stock]]+Table3[[#This Row],[056 Order]]+Table3[[#This Row],[0789 Order]]+Table3[[#This Row],[0788 Order]]+Table3[[#This Row],[In Transit]])/Table3[[#This Row],[Schedule]]*30,0) -> #DIV/0!
A11: 7 | D11: 15.88 | E11: 1 | F11: 6.19 | G11: 2.272 | H11: 15.88-0-1-ERW 1-PE | I11: ERW 1 | J11: NFC | L11: 0 | N11: 1940054 | P11: ='vsm req'!K11 -> 0 | Q11: =((D11-E11)*E11*0.0246615*F11*L11) -> 0 | T11: =ROUND((Q11+Table3[[#This Row],[In Transit]])/P11*30,0) -> #DIV/0! | Y11: =IF((45-Table3[[#This Row],[Coverage post order]])>0,Table3[[#This Row],[Schedule]]*1.5,0) -> #DIV/0! | Z11: =ROUND((Table3[[#This Row],[Stock]]+Table3[[#This Row],[056 Order]]+Table3[[#This Row],[0789 Order]]+Table3[[#This Row],[0788 Order]]+Table3[[#This Row],[In Transit]])/Table3[[#This Row],[Schedule]]*30,0) -> #DIV/0!
A12: 8 | C12: 943210 | D12: 15.88 | E12: 1.2 | F12: 6 | G12: 2.607 | H12: 15.88-0-1.2-ERW 1-PE | I12: ERW 1 | J12: NFC | L12: 602 | N12: 1940054 | P12: ='vsm req'!K12 -> 5000 | Q12: =((D12-E12)*E12*0.0246615*F12*L12) -> 1569.1864 | T12: =ROUND((Q12+Table3[[#This Row],[In Transit]])/P12*30,0) -> 9 | V12: 7500 | Y12: =IF((45-Table3[[#This Row],[Coverage post order]])>0,Table3[[#This Row],[Schedule]]*1.5,0) -> 0 | Z12: =ROUND((Table3[[#This Row],[Stock]]+Table3[[#This Row],[056 Order]]+Table3[[#This Row],[0789 Order]]+Table3[[#This Row],[0788 Order]]+Table3[[#This Row],[In Transit]])/Table3[[#This Row],[Schedule]]*30,0) -> 54 | AA12: 0789
A13: 9 | D13: 15.88 | E13: 1.4 | F13: 6 | G13: 2.607 | I13: ERW 1 | J13: NFC | L13: 2456 | P13: ='vsm req'!K13 -> 0 | Q13: =((D13-E13)*E13*0.0246615*F13*L13) -> 7367.0853 | T13: =ROUND((Q13+Table3[[#This Row],[In Transit]])/P13*30,0) -> #DIV/0! | Y13: =IF((45-Table3[[#This Row],[Coverage post order]])>0,Table3[[#This Row],[Schedule]]*1.5,0) -> #DIV/0! | Z13: =ROUND((Table3[[#This Row],[Stock]]+Table3[[#This Row],[056 Order]]+Table3[[#This Row],[0789 Order]]+Table3[[#This Row],[0788 Order]]+Table3[[#This Row],[In Transit]])/Table3[[#This Row],[Schedule]]*30,0) -> #DIV/0!
A14: 10 | D14: 15.88 | E14: 1.6 | F14: 6 | G14: 3.381 | H14: 15.88-0-1.6-ERW 1-PE | I14: ERW 1 | J14: NFC | L14: 3154 | N14: 1900224 | P14: ='vsm req'!K14 -> 1000 | Q14: =((D14-E14)*E14*0.0246615*F14*L14) -> 10663.03 | T14: =ROUND((Q14+Table3[[#This Row],[In Transit]])/P14*30,0) -> 320 | Y14: =IF((45-Table3[[#This Row],[Coverage post order]])>0,Table3[[#This Row],[Schedule]]*1.5,0) -> 0 | Z14: =ROUND((Table3[[#This Row],[Stock]]+Table3[[#This Row],[056 Order]]+Table3[[#This Row],[0789 Order]]+Table3[[#This Row],[0788 Order]]+Table3[[#This Row],[In Transit]])/Table3[[#This Row],[Schedule]]*30,0) -> 320
A15: 11 | C15: 943209 | D15: 15.88 | E15: 2 | F15: 6 | G15: 4.108 | H15: 15.88-0-2-ERW 1-PE | I15: ERW 1 | J15: NFC | L15: 0 | N15: 1940120 | P15: ='vsm req'!K15 -> 3000 | Q15: =((D15-E15)*E15*0.0246615*F15*L15) -> 0 | T15: =ROUND((Q15+Table3[[#This Row],[In Transit]])/P15*30,0) -> 0 | V15: 4500 | Y15: =IF((45-Table3[[#This Row],[Coverage post order]])>0,Table3[[#This Row],[Schedule]]*1.5,0) -> 0 | Z15: =ROUND((Table3[[#This Row],[Stock]]+Table3[[#This Row],[056 Order]]+Table3[[#This Row],[0789 Order]]+Table3[[#This Row],[0788 Order]]+Table3[[#This Row],[In Transit]])/Table3[[#This Row],[Schedule]]*30,0) -> 45 | AA15: 0789
A16: 12 | D16: 16.8 | E16: 2.4 | F16: 4.4 | G16: 3.75 | H16: 16.1-10.4-2.7-CEW-CEW | I16: ERW 1 | J16: NFC | L16: 0 | P16: ='vsm req'!K16 -> 0 | Q16: =((D16-E16)*E16*0.0246615*F16*L16) -> 0 | T16: =ROUND((Q16+Table3[[#This Row],[In Transit]])/P16*30,0) -> #DIV/0! | Y16: =IF((45-Table3[[#This Row],[Coverage post order]])>0,Table3[[#This Row],[Schedule]]*1.5,0) -> #DIV/0! | Z16: =ROUND((Table3[[#This Row],[Stock]]+Table3[[#This Row],[056 Order]]+Table3[[#This Row],[0789 Order]]+Table3[[#This Row],[0788 Order]]+Table3[[#This Row],[In Transit]])/Table3[[#This Row],[Schedule]]*30,0) -> #DIV/0!
A17: 13 | D17: 18.2 | E17: 1 | F17: 6.145 | G17: 2.607 | H17: 18.2-0-1-ERW 1-PE | I17: ERW 1 | J17: NFC | L17: 2400 | N17: 2288945 | P17: ='vsm req'!K17 -> 5000 | Q17: =((D17-E17)*E17*0.0246615*F17*L17) -> 6255.7742 | R17: 0 | T17: =ROUND((Q17+Table3[[#This Row],[In Transit]])/P17*30,0) -> 38 | Y17: =IF((45-Table3[[#This Row],[Coverage post order]])>0,Table3[[#This Row],[Schedule]]*1.5,0) -> 7500 | Z17: =ROUND((Table3[[#This Row],[Stock]]+Table3[[#This Row],[056 Order]]+Table3[[#This Row],[0789 Order]]+Table3[[#This Row],[0788 Order]]+Table3[[#This Row],[In Transit]])/Table3[[#This Row],[Schedule]]*30,0) -> 38 | AA17: don't log
A18: 14 | C18: 943210 | D18: 19.05 | E18: 1.4 | F18: 6 | G18: 3.656 | I18: ERW 2 | J18: NFC | L18: 1856 | M18: 3891285 | N18: 1931848 | P18: ='vsm req'!K18 -> 11000 | Q18: =((D18-E18)*E18*0.0246615*F18*L18) -> 6786.1188 | R18: 0 | T18: =ROUND((Q18+Table3[[#This Row],[In Transit]])/P18*30,0) -> 19 | U18: 10000 | Y18: =IF((45-Table3[[#This Row],[Coverage post order]])>0,Table3[[#This Row],[Schedule]]*1.5,0) -> 0 | Z18: =ROUND((Table3[[#This Row],[Stock]]+Table3[[#This Row],[056 Order]]+Table3[[#This Row],[0789 Order]]+Table3[[#This Row],[0788 Order]]+Table3[[#This Row],[In Transit]])/Table3[[#This Row],[Schedule]]*30,0) -> 46
A19: 15 | C19: 943209 | D19: 19.05 | E19: 1.6 | F19: 6 | G19: 4.062 | H19: 19.05-0-1.6-ERW 1-PE | I19: ERW 1 | J19: NFC | L19: 2851 | M19: 3498997 | N19: 2405716 | P19: 15000 | Q19: =((D19-E19)*E19*0.0246615*F19*L19) -> 11778.321 | R19: 0 | T19: =ROUND((Q19+Table3[[#This Row],[In Transit]])/P19*30,0) -> 24 | U19: 15000 | Y19: =IF((45-Table3[[#This Row],[Coverage post order]])>0,Table3[[#This Row],[Schedule]]*1.5,0) -> 0 | Z19: =ROUND((Table3[[#This Row],[Stock]]+Table3[[#This Row],[056 Order]]+Table3[[#This Row],[0789 Order]]+Table3[[#This Row],[0788 Order]]+Table3[[#This Row],[In Transit]])/Table3[[#This Row],[Schedule]]*30,0) -> 54
A20: 16 | D20: 19.05 | E20: 1.6 | F20: 6.2 | G20: 4.131 | H20: 19.05-0-1.6-ERW 1-PE | I20: ERW 1 | J20: NFC | L20: 0 | P20: ='vsm req'!K20 -> 0 | Q20: =((D20-E20)*E20*0.0246615*F20*L20) -> 0 | T20: =ROUND((Q20+Table3[[#This Row],[In Transit]])/P20*30,0) -> #DIV/0! | Y20: =IF((45-Table3[[#This Row],[Coverage post order]])>0,Table3[[#This Row],[Schedule]]*1.5,0) -> #DIV/0! | Z20: =ROUND((Table3[[#This Row],[Stock]]+Table3[[#This Row],[056 Order]]+Table3[[#This Row],[0789 Order]]+Table3[[#This Row],[0788 Order]]+Table3[[#This Row],[In Transit]])/Table3[[#This Row],[Schedule]]*30,0) -> #DIV/0!
A21: 17 | C21: 943209 | D21: 19.05 | E21: 2 | F21: 5.8 | G21: 4.878 | H21: 19.05-0-2-ERW 1-PE | I21: ERW 1 | J21: NFC | L21: 965 | N21: 1940292 | P21: ='vsm req'!K21 -> 17000 | Q21: =((D21-E21)*E21*0.0246615*F21*L21) -> 4706.8372 | T21: =ROUND((Q21+Table3[[#This Row],[In Transit]])/P21*30,0) -> 8 | V21: 25500 | Y21: =IF((45-Table3[[#This Row],[Coverage post order]])>0,Table3[[#This Row],[Schedule]]*1.5,0) -> 0 | Z21: =ROUND((Table3[[#This Row],[Stock]]+Table3[[#This Row],[056 Order]]+Table3[[#This Row],[0789 Order]]+Table3[[#This Row],[0788 Order]]+Table3[[#This Row],[In Transit]])/Table3[[#This Row],[Schedule]]*30,0) -> 53 | AA21: 0789
A22: 18 | C22: 943209 | D22: 19.05 | E22: 2 | F22: 5.841 | G22: 4.912 | H22: 19.05-0-2-ERW 1-PE | I22: ERW 1 | J22: NFC | L22: 0 | M22: 3673888 | P22: ='vsm req'!K22 -> 48000 | Q22: =((D22-E22)*E22*0.0246615*F22*L22) -> 0 | R22: 0 | T22: =ROUND((Q22+Table3[[#This Row],[In Transit]])/P22*30,0) -> 0 | U22: 72000 | Y22: =IF((45-Table3[[#This Row],[Coverage post order]])>0,Table3[[#This Row],[Schedule]]*1.5,0) -> 0 | Z22: =ROUND((Table3[[#This Row],[Stock]]+Table3[[#This Row],[056 Order]]+Table3[[#This Row],[0789 Order]]+Table3[[#This Row],[0788 Order]]+Table3[[#This Row],[In Transit]])/Table3[[#This Row],[Schedule]]*30,0) -> 45 | AA22: 056
A23: 19 | C23: 943209 | D23: 19.05 | E23: 2.3 | F23: 6 | G23: 6.651 | H23: 19.05-0-2.3-ERW 1-PE | I23: ERW 1 | J23: NFC | L23: 0 | M23: 3499232 | P23: ='vsm req'!K23 -> 4000 | Q23: =((D23-E23)*E23*0.0246615*F23*L23) -> 0 | T23: =ROUND((Q23+Table3[[#This Row],[In Transit]])/P23*30,0) -> 0 | U23: 6000 | Y23: =IF((45-Table3[[#This Row],[Coverage post order]])>0,Table3[[#This Row],[Schedule]]*1.5,0) -> 0 | Z23: =ROUND((Table3[[#This Row],[Stock]]+Table3[[#This Row],[056 Order]]+Table3[[#This Row],[0789 Order]]+Table3[[#This Row],[0788 Order]]+Table3[[#This Row],[In Transit]])/Table3[[#This Row],[Schedule]]*30,0) -> 45 | AA23: 056
A24: 20 | D24: 19.05 | E24: 2.3 | F24: 6.32 | G24: 6.651 | H24: 19.05-0-2.3-ERW 1-PE | I24: ERW 1 | J24: NFC | L24: 2870 | P24: ='vsm req'!K24 -> 0 | Q24: =((D24-E24)*E24*0.0246615*F24*L24) -> 17233.009 | T24: =ROUND((Q24+Table3[[#This Row],[In Transit]])/P24*30,0) -> #DIV/0! | Y24: =IF((45-Table3[[#This Row],[Coverage post order]])>0,Table3[[#This Row],[Schedule]]*1.5,0) -> #DIV/0! | Z24: =ROUND((Table3[[#This Row],[Stock]]+Table3[[#This Row],[056 Order]]+Table3[[#This Row],[0789 Order]]+Table3[[#This Row],[0788 Order]]+Table3[[#This Row],[In Transit]])/Table3[[#This Row],[Schedule]]*30,0) -> #DIV/0!
C25: 943209 | D25: 19.05 | E25: 2.3 | F25: 7 | L25: 2546 | M25: 3500582 | P25: ='vsm req'!K25 -> 30000 | Q25: =((D25-E25)*E25*0.0246615*F25*L25) -> 16932.402 | R25: 0 | T25: =ROUND((Q25+Table3[[#This Row],[In Transit]])/P25*30,0) -> 17 | U25: 45000 | Y25: =IF((45-Table3[[#This Row],[Coverage post order]])>0,Table3[[#This Row],[Schedule]]*1.5,0) -> 0 | Z25: =ROUND((Table3[[#This Row],[Stock]]+Table3[[#This Row],[056 Order]]+Table3[[#This Row],[0789 Order]]+Table3[[#This Row],[0788 Order]]+Table3[[#This Row],[In Transit]])/Table3[[#This Row],[Schedule]]*30,0) -> 62 | AA25: 056
D26: 19 | E26: 3.25 | F26: 6.2 | L26: 200 | P26: ='vsm req'!K26 -> 0 | Q26: =((D26-E26)*E26*0.0246615*F26*L26) -> 1565.3271 | T26: =ROUND((Q26+Table3[[#This Row],[In Transit]])/P26*30,0) -> #DIV/0! | Y26: =IF((45-Table3[[#This Row],[Coverage post order]])>0,Table3[[#This Row],[Schedule]]*1.5,0) -> #DIV/0! | Z26: =ROUND((Table3[[#This Row],[Stock]]+Table3[[#This Row],[056 Order]]+Table3[[#This Row],[0789 Order]]+Table3[[#This Row],[0788 Order]])/Table3[[#This Row],[Schedule]]*30,0) -> #DIV/0!
A27: 21 | C27: 943209 | D27: 21.4 | E27: 1.6 | F27: 6 | G27: 4.688 | H27: 21.4-0-1.6-ERW 1-PE | I27: ERW 1 | J27: NFC | L27: 0 | N27: 3219710 | P27: ='vsm req'!K27 -> 5000 | Q27: =((D27-E27)*E27*0.0246615*F27*L27) -> 0 | T27: =ROUND((Q27+Table3[[#This Row],[In Transit]])/P27*30,0) -> 0 | V27: 7500 | Y27: =IF((45-Table3[[#This Row],[Coverage post order]])>0,Table3[[#This Row],[Schedule]]*1.5,0) -> 0 | Z27: =ROUND((Table3[[#This Row],[Stock]]+Table3[[#This Row],[056 Order]]+Table3[[#This Row],[0789 Order]]+Table3[[#This Row],[0788 Order]]+Table3[[#This Row],[In Transit]])/Table3[[#This Row],[Schedule]]*30,0) -> 45 | AA27: 0789
A28: 22 | C28: 943209 | D28: 21.4 | E28: 2 | F28: 5.66 | I28: ERW 1 | J28: NFC | L28: 0 | N28: 2405717 | P28: ='vsm req'!K28 -> 0 | Q28: =((D28-E28)*E28*0.0246615*F28*L28) -> 0 | T28: =ROUND((Q28+Table3[[#This Row],[In Transit]])/P28*30,0) -> #DIV/0! | Y28: =IF((45-Table3[[#This Row],[Coverage post order]])>0,Table3[[#This Row],[Schedule]]*1.5,0) -> #DIV/0! | Z28: =ROUND((Table3[[#This Row],[Stock]]+Table3[[#This Row],[056 Order]]+Table3[[#This Row],[0789 Order]]+Table3[[#This Row],[0788 Order]]+Table3[[#This Row],[In Transit]])/Table3[[#This Row],[Schedule]]*30,0) -> #DIV/0! | AA28: 789
A29: 23 | D29: 22.2 | E29: 1.2 | F29: 5.3 | L29: 1143 | P29: ='vsm req'!K29 -> 9500 | Q29: =((D29-E29)*E29*0.0246615*F29*L29) -> 3764.8019 | R29: 0 | T29: =ROUND((Q29+Table3[[#This Row],[In Transit]])/P29*30,0) -> 12 | Y29: =IF((45-Table3[[#This Row],[Coverage post order]])>0,Table3[[#This Row],[Schedule]]*1.5,0) -> 14250 | Z29: =ROUND((Table3[[#This Row],[Stock]]+Table3[[#This Row],[056 Order]]+Table3[[#This Row],[0789 Order]]+Table3[[#This Row],[0788 Order]]+Table3[[#This Row],[In Transit]])/Table3[[#This Row],[Schedule]]*30,0) -> 12 | AA29: don't log
A30: 24 | C30: 943209 | D30: 22.2 | E30: 1.2 | F30: 5.87 | G30: 3.648 | H30: 22.23-0-1.2-ERW 1-PE | I30: ERW 1 | J30: NFC | L30: 5767 | M30: 3882110 | P30: ='vsm req'!K30 -> 10000 | Q30: =((D30-E30)*E30*0.0246615*F30*L30) -> 21038.176 | R30: 0 | T30: =ROUND((Q30+Table3[[#This Row],[In Transit]])/P30*30,0) -> 63 | U30: 21500 | Y30: =IF((45-Table3[[#This Row],[Coverage post order]])>0,Table3[[#This Row],[Schedule]]*1.5,0) -> 0 | Z30: =ROUND((Table3[[#This Row],[Stock]]+Table3[[#This Row],[056 Order]]+Table3[[#This Row],[0789 Order]]+Table3[[#This Row],[0788 Order]]+Table3[[#This Row],[In Transit]])/Table3[[#This Row],[Schedule]]*30,0) -> 128
A31: 25 | C31: 943209 | D31: 22.2 | E31: 1.4 | F31: 6 | G31: 4.309 | I31: ERW 2 | J31: NFC | L31: 0 | M31: 3829175 | P31: ='vsm req'!K31 -> 6000 | Q31: =((D31-E31)*E31*0.0246615*F31*L31) -> 0 | T31: =ROUND((Q31+Table3[[#This Row],[In Transit]])/P31*30,0) -> 0 | U31: =7500+9000 -> 16500 | Y31: =IF((45-Table3[[#This Row],[Coverage post order]])>0,Table3[[#This Row],[Schedule]]*1.5,0) -> 0 | Z31: =ROUND((Table3[[#This Row],[Stock]]+Table3[[#This Row],[056 Order]]+Table3[[#This Row],[0789 Order]]+Table3[[#This Row],[0788 Order]]+Table3[[#This Row],[In Transit]])/Table3[[#This Row],[Schedule]]*30,0) -> 83 | AA31: 056
A32: 26 | C32: 943209 | D32: 22.2 | E32: 1.6 | F32: 5.27 | G32: 4.609 | H32: 22.23-0-1.6-ERW 1-PE | I32: ERW 1 | J32: NFC | L32: 8588 | N32: 3575894 | P32: 10000 | Q32: =((D32-E32)*E32*0.0246615*F32*L32) -> 36788.268 | R32: 0 | T32: =ROUND((Q32+Table3[[#This Row],[In Transit]])/P32*30,0) -> 110 | V32: 15000 | Y32: =IF((45-Table3[[#This Row],[Coverage post order]])>0,Table3[[#This Row],[Schedule]]*1.5,0) -> 0 | Z32: =ROUND((Table3[[#This Row],[Stock]]+Table3[[#This Row],[056 Order]]+Table3[[#This Row],[0789 Order]]+Table3[[#This Row],[0788 Order]]+Table3[[#This Row],[In Transit]])/Table3[[#This Row],[Schedule]]*30,0) -> 155 | AA32: 0789
A33: 27 | C33: 943209 | D33: 22.2 | E33: 1.6 | F33: 5.264 | G33: 4.284 | H33: 22.23-0-1.6-ERW 1-PE | I33: ERW 1 | J33: NFC | L33: 793 | M33: 3501116 | P33: ='vsm req'!K33 -> 55000 | Q33: =((D33-E33)*E33*0.0246615*F33*L33) -> 3393.093 | R33: 11209 | T33: =ROUND((Q33+Table3[[#This Row],[In Transit]])/P33*30,0) -> 8 | U33: =52000+82500 -> 134500 | Y33: =IF((45-Table3[[#This Row],[Coverage post order]])>0,Table3[[#This Row],[Schedule]]*1.5,0) -> 0 | Z33: =ROUND((Table3[[#This Row],[Stock]]+Table3[[#This Row],[056 Order]]+Table3[[#This Row],[0789 Order]]+Table3[[#This Row],[0788 Order]]+Table3[[#This Row],[In Transit]])/Table3[[#This Row],[Schedule]]*30,0) -> 81 | AA33: 056 | AB33: x
A34: 28 | C34: 943209 | D34: 22.2 | E34: 1.6 | F34: 5.685 | G34: 4.877 | H34: 22.23-0-1.6-ERW 1-PE | I34: ERW 1 | J34: NFC | L34: 6031 | M34: 4173571 | N34: 3570690 | P34: ='vsm req'!K34 -> 0 | Q34: =((D34-E34)*E34*0.0246615*F34*L34) -> 27869.327 | R34: 20590 | T34: =ROUND((Q34+Table3[[#This Row],[In Transit]])/P34*30,0) -> #DIV/0! | U34: 75000 | Y34: =IF((45-Table3[[#This Row],[Coverage post order]])>0,Table3[[#This Row],[Schedule]]*1.5,0) -> #DIV/0! | Z34: =ROUND((Table3[[#This Row],[Stock]]+Table3[[#This Row],[056 Order]]+Table3[[#This Row],[0789 Order]]+Table3[[#This Row],[0788 Order]]+Table3[[#This Row],[In Transit]])/Table3[[#This Row],[Schedule]]*30,0) -> #DIV/0!
A35: 30 | C35: 943209 | D35: 22.2 | E35: 1.6 | F35: 5.67 | G35: 4.877 | H35: 22.23-0-1.6-ERW 1-PE | I35: ERW 1 | J35: NFC | L35: 4545 | M35: 3954021 | N35: 4055022 | P35: ='vsm req'!K36 -> 50000 | Q35: =((D35-E35)*E35*0.0246615*F35*L35) -> 20947.087 | R35: 18649 | T35: =ROUND((Q35+Table3[[#This Row],[In Transit]])/P35*30,0) -> 24 | U35: 31000 | V35: 75000 | Y35: =IF((45-Table3[[#This Row],[Coverage post order]])>0,Table3[[#This Row],[Schedule]]*1.5,0) -> 0 | Z35: =ROUND((Table3[[#This Row],[Stock]]+Table3[[#This Row],[056 Order]]+Table3[[#This Row],[0789 Order]]+Table3[[#This Row],[0788 Order]]+Table3[[#This Row],[In Transit]])/Table3[[#This Row],[Schedule]]*30,0) -> 87 | AA35: 0789
A36: 31 | C36: 943209 | D36: 22.2 | E36: 2 | F36: 5.1 | G36: 5.081 | H36: 22.23-0-2-ERW 1-PE | I36: ERW 1 | J36: NFC | L36: 0 | M36: 3500554 | P36: ='vsm req'!K37 -> 0 | Q36: =((D36-E36)*E36*0.0246615*F36*L36) -> 0 | R36: 0 | T36: =ROUND((Q36+Table3[[#This Row],[In Transit]])/P36*30,0) -> #DIV/0! | Y36: =IF((45-Table3[[#This Row],[Coverage post order]])>0,Table3[[#This Row],[Schedule]]*1.5,0) -> #DIV/0! | Z36: =ROUND((Table3[[#This Row],[Stock]]+Table3[[#This Row],[056 Order]]+Table3[[#This Row],[0789 Order]]+Table3[[#This Row],[0788 Order]]+Table3[[#This Row],[In Transit]])/Table3[[#This Row],[Schedule]]*30,0) -> #DIV/0!
A37: 32 | C37: 943209 | D37: 22.2 | E37: 2 | F37: 5.4 | G37: 5.38 | H37: 22.23-0-2-ERW 1-FC | I37: ERW 1 | J37: FC | K37: CR | L37: 6354 | N37: 2431251 | P37: 10000 | Q37: =((D37-E37)*E37*0.0246615*F37*L37) -> 34185.491 | T37: =ROUND((Q37+Table3[[#This Row],[In Transit]])/P37*30,0) -> 103 | Y37: =IF((45-Table3[[#This Row],[Coverage post order]])>0,Table3[[#This Row],[Schedule]]*1.5,0) -> 0 | Z37: =ROUND((Table3[[#This Row],[Stock]]+Table3[[#This Row],[056 Order]]+Table3[[#This Row],[0789 Order]]+Table3[[#This Row],[0788 Order]]+Table3[[#This Row],[In Transit]])/Table3[[#This Row],[Schedule]]*30,0) -> 103 | AA37: 789
A38: 35 | C38: 943209 | D38: 22.2 | E38: 2 | F38: 5.951 | G38: 5.928 | H38: 22.23-0-2-ERW 1-PE | I38: ERW 1 | J38: NFC | L38: 9778 | M38: 3905466 | P38: ='vsm req'!K41 -> 159000 | Q38: =((D38-E38)*E38*0.0246615*F38*L38) -> 57975.011 | R38: 24941 | T38: =ROUND((Q38+Table3[[#This Row],[In Transit]])/P38*30,0) -> 16 | U38: =145000+238500 -> 383500 | Y38: =IF((45-Table3[[#This Row],[Coverage post order]])>0,Table3[[#This Row],[Schedule]]*1.5,0) -> 0 | Z38: =ROUND((Table3[[#This Row],[Stock]]+Table3[[#This Row],[056 Order]]+Table3[[#This Row],[0789 Order]]+Table3[[#This Row],[0788 Order]]+Table3[[#This Row],[In Transit]])/Table3[[#This Row],[Schedule]]*30,0) -> 88 | AA38: 056
A39: 36 | C39: 943209 | D39: 22.2 | E39: 2 | F39: 6 | G39: 5.978 | H39: 22.23-0-2-ERW 2-FC | I39: ERW 2 | J39: FC | L39: 3349 | M39: 3502494 | N39: 3410966 | P39: ='vsm req'!K42 -> 60000 | Q39: =((D39-E39)*E39*0.0246615*F39*L39) -> 20020.147 | R39: 15233 | T39: =ROUND((Q39+Table3[[#This Row],[In Transit]])/P39*30,0) -> 18 | U39: 67500 | Y39: =IF((45-Table3[[#This Row],[Coverage post order]])>0,Table3[[#This Row],[Schedule]]*1.5,0) -> 0 | Z39: =ROUND((Table3[[#This Row],[Stock]]+Table3[[#This Row],[056 Order]]+Table3[[#This Row],[0789 Order]]+Table3[[#This Row],[0788 Order]]+Table3[[#This Row],[In Transit]])/Table3[[#This Row],[Schedule]]*30,0) -> 51 | AA39: 56 | AB39: x
A40: 39 | C40: 943210 | D40: 25.4 | E40: 1.4 | F40: 5.531 | G40: 4.583 | I40: ERW 2 | J40: FC | L40: 3651 | M40: 3501900 | P40: ='vsm req'!K45 -> 0 | Q40: =((D40-E40)*E40*0.0246615*F40*L40) -> 16733.017 | R40: 0 | T40: =ROUND((Q40+Table3[[#This Row],[In Transit]])/P40*30,0) -> #DIV/0! | Y40: =IF((45-Table3[[#This Row],[Coverage post order]])>0,Table3[[#This Row],[Schedule]]*1.5,0) -> #DIV/0! | Z40: =ROUND((Table3[[#This Row],[Stock]]+Table3[[#This Row],[056 Order]]+Table3[[#This Row],[0789 Order]]+Table3[[#This Row],[0788 Order]]+Table3[[#This Row],[In Transit]])/Table3[[#This Row],[Schedule]]*30,0) -> #DIV/0! | AA40: 30 MT order
...
